Workbook

Sheet VISUAL PLANNING - CA
A1: Scenario List | D1: Klasifikasi | I1: Concept Visual Planning | P1: Revision 1 | Q1: Revision 1 | V1: Revision 2 | W1: Revision 2 | AB1: QC Concept Visual Planning | AC1: Quality Check Description | AJ1: Visual Planning | AQ1: Revision 1 | AR1: Revision 1 | AW1: Revision 2 | AX1: Revision 2 | BC1: QC Visual Planning | BD1: Quality Visual Planning
A2: No | B2: Scenario Name | C2: Scenario Code | D2: Level Konsep Visual Planning | E2: Level Visual Planning | F2: PIC Penentu | H2: Level | I2: PIC | J2: Start Time | K2: Status | L2: Finish Time | M2: Duration (Minute) | N2: Duration Pause (Minute) | O2: Duration Final (Hour) | Q2: PIC Rev 1 | R2: Start Time | S2: Status | T2: Finish Time | U2: Revision Percentage | W2: PIC Rev 2 | X2: Start Time | Y2: Status | Z2: Finish Time | AA2: Revision Percentage | AC2: PIC QC | AD2: Start Time | AE2: Status | AF2: Finish Time | AG2: QC Count | AI2: Level | AJ2: PIC | AK2: Start Time | AL2: Status | AM2: Finish Time | AN2: Duration (Minute) | AO2: Duration Pause (Minute) | AP2: Duration Final (Hour) | AR2: PIC Rev 1 | AS2: Start Time | AT2: Status | AU2: Finish Time | AV2: Revision Percentage | AX2: PIC Rev 2 | AY2: Start Time | AZ2: Status | BA2: Finish Time | BB2: Revision Percentage | BD2: PIC QC | BE2: Start Time | BF2: Status | BG2: Finish Time | BH2: QC Count
A3: =IF(B3="","",COUNTA($B$3:B3)) -> 1 | B3: Static Target Shooting | C3: =IF(B3="","", "PDSSVP"&TEXT(COUNTA($B$3:B3),"000")) -> PDSSVP001 | D3: 2 | E3: 2 | F3: Dian Hasanudin | H3: =D3 -> 2 | I3: Muhamad Ade Saputra | J3: 46135.492 | K3: Done | L3: 46136.706 | M3: =IF(AND(J3<>"",L3<>""),(L3-J3)*1440,"") -> 1748 | N3: =IF( INT(J3)=INT(L3), IF( AND(MOD(J3,1)<TIME(12,0,0), MOD(L3,1)>TIME(12,0,0)), 60, 0 ), IF( MOD(L3,1)<=TIME(12,0,0), (INT(L3)-INT(J3))*960, (INT(L3)-INT(J3))*1020 ) ) -> 1020 | O3: =(M3-N3)/60 -> 12.133333 | P3: =S3 -> Done | Q3: Muhamad Ade Saputra | R3: =if(Q3<>"", if(R3="",NOW(),R3),"") -> 46148.457 | S3: Done | T3: =if(S3="Done", if(T3="",NOW(),T3),"") -> 46148.697 | V3: =Y3 | X3: =if(W3<>"", if(X3="",NOW(),X3),"") | Z3: =if(Y3="Done", if(Z3="",NOW(),Z3),"") | AB3: =AE3 | AD3: =if(AC3<>"", if(AD3="",NOW(),AD3),"") | AF3: =if(AE3="Done", if(AF3="",NOW(),AF3),"") | AG3: 0 | AI3: =E3 -> 2 | AJ3: Faaidh Abdurrazzak | AK3: 46136.421 | AL3: Done | AM3: 46139.704 | AN3: =IF(AND(AK3<>"",AM3<>""),(AM3-AK3)*1440,"") -> 4728.35 | AO3: =IF( INT(AK3)=INT(AM3), IF( AND(MOD(AK3,1)<TIME(12,0,0), MOD(AM3,1)>TIME(12,0,0)), 60, 0 ), IF( MOD(AM3,1)<=TIME(12,0,0), (INT(AM3)-INT(AK3))*960, (INT(AM3)-INT(AK3))*1020 ) ) -> 3060 | AP3: =(AN3-AO3)/60 -> 27.805833 | AQ3: =AT3 -> Done | AR3: Faaidh Abdurrazzak | AS3: =if(AR3<>"", if(AS3="",NOW(),AS3),"") -> 46148.633 | AT3: Done | AU3: =if(AT3="Done", if(AU3="",NOW(),AU3),"") -> 46148.705 | AW3: =AZ3 | AY3: =if(AX3<>"", if(AY3="",NOW(),AY3),"") | BA3: =if(AZ3="Done", if(BA3="",NOW(),BA3),"") | BC3: =BF3 | BE3: =if(BD3<>"", if(BE3="",NOW(),BE3),"") | BG3: =if(BF3="Done", if(BG3="",NOW(),BG3),"") | BH3: 1
A4: =IF(B4="","",COUNTA($B$3:B4)) -> 2 | B4: Moving Target Shooting | C4: =IF(B4="","", "PDSSVP"&TEXT(COUNTA($B$3:B4),"000")) -> PDSSVP002 | D4: 2 | E4: 2 | F4: Dian Hasanudin | H4: =D4 -> 2 | I4: Muhamad Ade Saputra | J4: 46139.402 | K4: Done | L4: 46140.708 | M4: =IF(AND(J4<>"",L4<>""),(L4-J4)*1440,"") -> 1880.9333 | N4: =IF( INT(J4)=INT(L4), IF( AND(MOD(J4,1)<TIME(12,0,0), MOD(L4,1)>TIME(12,0,0)), 60, 0 ), IF( MOD(L4,1)<=TIME(12,0,0), (INT(L4)-INT(J4))*960, (INT(L4)-INT(J4))*1020 ) ) -> 1020 | O4: =(M4-N4)/60 -> 14.348889 | P4: =S4 -> Done | Q4: Muhamad Ade Saputra | R4: =if(Q4<>"", if(R4="",NOW(),R4),"") -> 46149.386 | S4: Done | T4: =if(S4="Done", if(T4="",NOW(),T4),"") -> 46149.613 | V4: =Y4 | X4: =if(W4<>"", if(X4="",NOW(),X4),"") | Z4: =if(Y4="Done", if(Z4="",NOW(),Z4),"") | AB4: =AE4 | AD4: =if(AC4<>"", if(AD4="",NOW(),AD4),"") | AF4: =if(AE4="Done", if(AF4="",NOW(),AF4),"") | AG4: 0 | AI4: =E4 -> 2 | AJ4: Faaidh Abdurrazzak | AK4: 46140.379 | AL4: Done | AM4: 46141.706 | AN4: =IF(AND(AK4<>"",AM4<>""),(AM4-AK4)*1440,"") -> 1911.6333 | AO4: =IF( INT(AK4)=INT(AM4), IF( AND(MOD(AK4,1)<TIME(12,0,0), MOD(AM4,1)>TIME(12,0,0)), 60, 0 ), IF( MOD(AM4,1)<=TIME(12,0,0), (INT(AM4)-INT(AK4))*960, (INT(AM4)-INT(AK4))*1020 ) ) -> 1020 | AP4: =(AN4-AO4)/60 -> 14.860556 | AQ4: =AT4 -> Done | AR4: Faaidh Abdurrazzak | AS4: =if(AR4<>"", if(AS4="",NOW(),AS4),"") -> 46149.649 | AT4: Done | AU4: =if(AT4="Done", if(AU4="",NOW(),AU4),"") -> 46149.694 | AW4: =AZ4 | AY4: =if(AX4<>"", if(AY4="",NOW(),AY4),"") | BA4: =if(AZ4="Done", if(BA4="",NOW(),BA4),"") | BC4: =BF4 | BE4: =if(BD4<>"", if(BE4="",NOW(),BE4),"") | BG4: =if(BF4="Done", if(BG4="",NOW(),BG4),"") | BH4: 0
A5: =IF(B5="","",COUNTA($B$3:B5)) -> 3 | B5: Multiple Target Engangement | C5: =IF(B5="","", "PDSSVP"&TEXT(COUNTA($B$3:B5),"000")) -> PDSSVP003 | D5: 2 | E5: 2 | F5: Dian Hasanudin | H5: =D5 -> 2 | I5: Muhamad Ade Saputra | J5: 46146.375 | K5: Done | L5: =if(K5="Done", if(L5="",NOW(),L5),"") -> 46148.379 | M5: =IF(AND(J5<>"",L5<>""),(L5-J5)*1440,"") -> 2886.2287 | N5: =IF( INT(J5)=INT(L5), IF( AND(MOD(J5,1)<TIME(12,0,0), MOD(L5,1)>TIME(12,0,0)), 60, 0 ), IF( MOD(L5,1)<=TIME(12,0,0), (INT(L5)-INT(J5))*960, (INT(L5)-INT(J5))*1020 ) ) -> 1920 | O5: =(M5-N5)/60 -> 16.103811 | P5: =S5 -> Done | Q5: Muhamad Ade Saputra | R5: =if(Q5<>"", if(R5="",NOW(),R5),"") -> 46150.418 | S5: Done | T5: =if(S5="Done", if(T5="",NOW(),T5),"") -> 46150.595 | V5: =Y5 | X5: =if(W5<>"", if(X5="",NOW(),X5),"") | Z5: =if(Y5="Done", if(Z5="",NOW(),Z5),"") | AB5: =AE5 | AD5: =if(AC5<>"", if(AD5="",NOW(),AD5),"") | AF5: =if(AE5="Done", if(AF5="",NOW(),AF5),"") | AG5: 0 | AI5: =E5 -> 2 | AJ5: Faaidh Abdurrazzak | AK5: 46147.375 | AL5: Done | AM5: =if(AL5="Done", if(AM5="",NOW(),AM5),"") -> 46147.709 | AN5: =IF(AND(AK5<>"",AM5<>""),(AM5-AK5)*1440,"") -> 481.08888 | AO5: =IF( INT(AK5)=INT(AM5), IF( AND(MOD(AK5,1)<TIME(12,0,0), MOD(AM5,1)>TIME(12,0,0)), 60, 0 ), IF( MOD(AM5,1)<=TIME(12,0,0), (INT(AM5)-INT(AK5))*960, (INT(AM5)-INT(AK5))*1020 ) ) -> 60 | AP5: =(AN5-AO5)/60 -> 7.0181481 | AQ5: =AT5 -> Done | AR5: Faaidh Abdurrazzak | AS5: =if(AR5<>"", if(AS5="",NOW(),AS5),"") -> 46150.613 | AT5: Done | AU5: =if(AT5="Done", if(AU5="",NOW(),AU5),"") -> 46150.684 | AW5: =AZ5 | AY5: =if(AX5<>"", if(AY5="",NOW(),AY5),"") | BA5: =if(AZ5="Done", if(BA5="",NOW(),BA5),"") | BC5: =BF5 | BE5: =if(BD5<>"", if(BE5="",NOW(),BE5),"") | BG5: =if(BF5="Done", if(BG5="",NOW(),BG5),"") | BH5: 0
A6: =IF(B6="","",COUNTA($B$3:B6)) -> 4 | B6: Pop Up Target Shooting | C6: =IF(B6="","", "PDSSVP"&TEXT(COUNTA($B$3:B6),"000")) -> PDSSVP004 | D6: 2 | E6: 2 | F6: Dian Hasanudin | H6: =D6 -> 2 | I6: Muhamad Ade Saputra | J6: 46141.379 | K6: Done | L6: 46142.686 | M6: =IF(AND(J6<>"",L6<>""),(L6-J6)*1440,"") -> 1881.1667 | N6: =IF( INT(J6)=INT(L6), IF( AND(MOD(J6,1)<TIME(12,0,0), MOD(L6,1)>TIME(12,0,0)), 60, 0 ), IF( MOD(L6,1)<=TIME(12,0,0), (INT(L6)-INT(J6))*960, (INT(L6)-INT(J6))*1020 ) ) -> 1020 | O6: =(M6-N6)/60 -> 14.352778 | P6: =S6 -> Done | Q6: Muhamad Ade Saputra | R6: =if(Q6<>"", if(R6="",NOW(),R6),"") -> 46149.614 | S6: Done | T6: =if(S6="Done", if(T6="",NOW(),T6),"") -> 46149.698 | V6: =Y6 | X6: =if(W6<>"", if(X6="",NOW(),X6),"") | Z6: =if(Y6="Done", if(Z6="",NOW(),Z6),"") | AB6: =AE6 | AD6: =if(AC6<>"", if(AD6="",NOW(),AD6),"") | AF6: =if(AE6="Done", if(AF6="",NOW(),AF6),"") | AG6: 0 | AI6: =E6 -> 2 | AJ6: Faaidh Abdurrazzak | AK6: 46142.378 | AL6: Done | AM6: 46146.705 | AN6: =IF(AND(AK6<>"",AM6<>""),(AM6-AK6)*1440,"") -> 6231.5 | AO6: =IF( INT(AK6)=INT(AM6), IF( AND(MOD(AK6,1)<TIME(12,0,0), MOD(AM6,1)>TIME(12,0,0)), 60, 0 ), IF( MOD(AM6,1)<=TIME(12,0,0), (INT(AM6)-INT(AK6))*960, (INT(AM6)-INT(AK6))*1020 ) ) -> 4080 | AP6: =(AN6-AO6)/60 -> 35.858333 | AQ6: =AT6 -> Done | AR6: Faaidh Abdurrazzak | AS6: =if(AR6<>"", if(AS6="",NOW(),AS6),"") -> 46150.395 | AT6: Done | AU6: =if(AT6="Done", if(AU6="",NOW(),AU6),"") -> 46150.588 | AW6: =AZ6 | AY6: =if(AX6<>"", if(AY6="",NOW(),AY6),"") | BA6: =if(AZ6="Done", if(BA6="",NOW(),BA6),"") | BC6: =BF6 | BE6: =if(BD6<>"", if(BE6="",NOW(),BE6),"") | BG6: =if(BF6="Done", if(BG6="",NOW(),BG6),"") | BH6: 0
A7: =IF(B7="","",COUNTA($B$3:B7)) -> 5 | B7: Tactical Shooting Scenario | C7: =IF(B7="","", "PDSSVP"&TEXT(COUNTA($B$3:B7),"000")) -> PDSSVP005 | H7: =D7 | J7: =if(I7<>"", if(J7="",NOW(),J7),"") | L7: =if(K7="Done", if(L7="",NOW(),L7),"") | M7: =IF(AND(J7<>"",L7<>""),(L7-J7)*1440,"") | N7: =IF( INT(J7)=INT(L7), IF( AND(MOD(J7,1)<TIME(12,0,0), MOD(L7,1)>TIME(12,0,0)), 60, 0 ), IF( MOD(L7,1)<=TIME(12,0,0), (INT(L7)-INT(J7))*960, (INT(L7)-INT(J7))*1020 ) ) -> 0 | O7: =(M7-N7)/60 -> 0 | P7: =S7 | R7: =if(Q7<>"", if(R7="",NOW(),R7),"") | T7: =if(S7="Done", if(T7="",NOW(),T7),"") | V7: =Y7 | X7: =if(W7<>"", if(X7="",NOW(),X7),"") | Z7: =if(Y7="Done", if(Z7="",NOW(),Z7),"") | AB7: =AE7 | AD7: =if(AC7<>"", if(AD7="",NOW(),AD7),"") | AF7: =if(AE7="Done", if(AF7="",NOW(),AF7),"") | AG7: 0 | AI7: =E7 | AK7: =if(AJ7<>"", if(AK7="",NOW(),AK7),"") | AM7: =if(AL7="Done", if(AM7="",NOW(),AM7),"") | AN7: =IF(AND(AK7<>"",AM7<>""),(AM7-AK7)*1440,"") | AO7: =IF( INT(AK7)=INT(AM7), IF( AND(MOD(AK7,1)<TIME(12,0,0), MOD(AM7,1)>TIME(12,0,0)), 60, 0 ), IF( MOD(AM7,1)<=TIME(12,0,0), (INT(AM7)-INT(AK7))*960, (INT(AM7)-INT(AK7))*1020 ) ) -> 0 | AP7: =(AN7-AO7)/60 -> 0 | AQ7: =AT7 | AS7: =if(AR7<>"", if(AS7="",NOW(),AS7),"") | AU7: =if(AT7="Done", if(AU7="",NOW(),AU7),"") | AW7: =AZ7 | AY7: =if(AX7<>"", if(AY7="",NOW(),AY7),"") | BA7: =if(AZ7="Done", if(BA7="",NOW(),BA7),"") | BC7: =BF7 | BE7: =if(BD7<>"", if(BE7="",NOW(),BE7),"") | BG7: =if(BF7="Done", if(BG7="",NOW(),BG7),"") | BH7: 0
A8: =IF(B8="","",COUNTA($B$3:B8)) -> 6 | B8: Reaction Shooting Drill | C8: =IF(B8="","", "PDSSVP"&TEXT(COUNTA($B$3:B8),"000")) -> PDSSVP006 | H8: =D8 | J8: =if(I8<>"", if(J8="",NOW(),J8),"") | L8: =if(K8="Done", if(L8="",NOW(),L8),"") | M8: =IF(AND(J8<>"",L8<>""),(L8-J8)*1440,"") | N8: =IF( INT(J8)=INT(L8), IF( AND(MOD(J8,1)<TIME(12,0,0), MOD(L8,1)>TIME(12,0,0)), 60, 0 ), IF( MOD(L8,1)<=TIME(12,0,0), (INT(L8)-INT(J8))*960, (INT(L8)-INT(J8))*1020 ) ) -> 0 | O8: =(M8-N8)/60 -> 0 | P8: =S8 | R8: =if(Q8<>"", if(R8="",NOW(),R8),"") | T8: =if(S8="Done", if(T8="",NOW(),T8),"") | V8: =Y8 | X8: =if(W8<>"", if(X8="",NOW(),X8),"") | Z8: =if(Y8="Done", if(Z8="",NOW(),Z8),"") | AB8: =AE8 | AD8: =if(AC8<>"", if(AD8="",NOW(),AD8),"") | AF8: =if(AE8="Done", if(AF8="",NOW(),AF8),"") | AG8: 0 | AI8: =E8 | AK8: =if(AJ8<>"", if(AK8="",NOW(),AK8),"") | AM8: =if(AL8="Done", if(AM8="",NOW(),AM8),"") | AN8: =IF(AND(AK8<>"",AM8<>""),(AM8-AK8)*1440,"") | AO8: =IF( INT(AK8)=INT(AM8), IF( AND(MOD(AK8,1)<TIME(12,0,0), MOD(AM8,1)>TIME(12,0,0)), 60, 0 ), IF( MOD(AM8,1)<=TIME(12,0,0), (INT(AM8)-INT(AK8))*960, (INT(AM8)-INT(AK8))*1020 ) ) -> 0 | AP8: =(AN8-AO8)/60 -> 0 | AQ8: =AT8 | AS8: =if(AR8<>"", if(AS8="",NOW(),AS8),"") | AU8: =if(AT8="Done", if(AU8="",NOW(),AU8),"") | AW8: =AZ8 | AY8: =if(AX8<>"", if(AY8="",NOW(),AY8),"") | BA8: =if(AZ8="Done", if(BA8="",NOW(),BA8),"") | BC8: =BF8 | BE8: =if(BD8<>"", if(BE8="",NOW(),BE8),"") | BG8: =if(BF8="Done", if(BG8="",NOW(),BG8),"") | BH8: 0
A9: =IF(B9="","",COUNTA($B$3:B9)) | C9: =IF(B9="","", "PDSSVP"&TEXT(COUNTA($B$3:B9),"000")) | H9: =D9 | J9: =if(I9<>"", if(J9="",NOW(),J9),"") | L9: =if(K9="Done", if(L9="",NOW(),L9),"") | M9: =IF(AND(J9<>"",L9<>""),(L9-J9)*1440,"") | N9: =IF( INT(J9)=INT(L9), IF( AND(MOD(J9,1)<TIME(12,0,0), MOD(L9,1)>TIME(12,0,0)), 60, 0 ), IF( MOD(L9,1)<=TIME(12,0,0), (INT(L9)-INT(J9))*960, (INT(L9)-INT(J9))*1020 ) ) -> 0 | O9: =(M9-N9)/60 -> 0 | P9: =S9 | R9: =if(Q9<>"", if(R9="",NOW(),R9),"") | T9: =if(S9="Done", if(T9="",NOW(),T9),"") | V9: =Y9 | X9: =if(W9<>"", if(X9="",NOW(),X9),"") | Z9: =if(Y9="Done", if(Z9="",NOW(),Z9),"") | AB9: =AE9 | AD9: =if(AC9<>"", if(AD9="",NOW(),AD9),"") | AF9: =if(AE9="Done", if(AF9="",NOW(),AF9),"") | AG9: 0 | AI9: =E9 | AK9: =if(AJ9<>"", if(AK9="",NOW(),AK9),"") | AM9: =if(AL9="Done", if(AM9="",NOW(),AM9),"") | AN9: =IF(AND(AK9<>"",AM9<>""),(AM9-AK9)*1440,"") | AO9: =IF( INT(AK9)=INT(AM9), IF( AND(MOD(AK9,1)<TIME(12,0,0), MOD(AM9,1)>TIME(12,0,0)), 60, 0 ), IF( MOD(AM9,1)<=TIME(12,0,0), (INT(AM9)-INT(AK9))*960, (INT(AM9)-INT(AK9))*1020 ) ) -> 0 | AP9: =(AN9-AO9)/60 -> 0 | AQ9: =AT9 | AS9: =if(AR9<>"", if(AS9="",NOW(),AS9),"") | AU9: =if(AT9="Done", if(AU9="",NOW(),AU9),"") | AW9: =AZ9 | AY9: =if(AX9<>"", if(AY9="",NOW(),AY9),"") | BA9: =if(AZ9="Done", if(BA9="",NOW(),BA9),"") | BC9: =BF9 | BE9: =if(BD9<>"", if(BE9="",NOW(),BE9),"") | BG9: =if(BF9="Done", if(BG9="",NOW(),BG9),"") | BH9: 0
A10: =IF(B10="","",COUNTA($B$3:B10)) | C10: =IF(B10="","", "PDSSVP"&TEXT(COUNTA($B$3:B10),"000")) | H10: =D10 | J10: =if(I10<>"", if(J10="",NOW(),J10),"") | L10: =if(K10="Done", if(L10="",NOW(),L10),"") | M10: =IF(AND(J10<>"",L10<>""),(L10-J10)*1440,"") | N10: =IF( INT(J10)=INT(L10), IF( AND(MOD(J10,1)<TIME(12,0,0), MOD(L10,1)>TIME(12,0,0)), 60, 0 ), IF( MOD(L10,1)<=TIME(12,0,0), (INT(L10)-INT(J10))*960, (INT(L10)-INT(J10))*1020 ) ) -> 0 | O10: =(M10-N10)/60 -> 0 | P10: =S10 | R10: =if(Q10<>"", if(R10="",NOW(),R10),"") | T10: =if(S10="Done", if(T10="",NOW(),T10),"") | V10: =Y10 | X10: =if(W10<>"", if(X10="",NOW(),X10),"") | Z10: =if(Y10="Done", if(Z10="",NOW(),Z10),"") | AB10: =AE10 | AD10: =if(AC10<>"", if(AD10="",NOW(),AD10),"") | AF10: =if(AE10="Done", if(AF10="",NOW(),AF10),"") | AG10: 0 | AI10: =E10 | AK10: =if(AJ10<>"", if(AK10="",NOW(),AK10),"") | AM10: =if(AL10="Done", if(AM10="",NOW(),AM10),"") | AN10: =IF(AND(AK10<>"",AM10<>""),(AM10-AK10)*1440,"") | AO10: =IF( INT(AK10)=INT(AM10), IF( AND(MOD(AK10,1)<TIME(12,0,0), MOD(AM10,1)>TIME(12,0,0)), 60, 0 ), IF( MOD(AM10,1)<=TIME(12,0,0), (INT(AM10)-INT(AK10))*960, (INT(AM10)-INT(AK10))*1020 ) ) -> 0 | AP10: =(AN10-AO10)/60 -> 0 | AQ10: =AT10 | AS10: =if(AR10<>"", if(AS10="",NOW(),AS10),"") | AU10: =if(AT10="Done", if(AU10="",NOW(),AU10),"") | AW10: =AZ10 | AY10: =if(AX10<>"", if(AY10="",NOW(),AY10),"") | BA10: =if(AZ10="Done", if(BA10="",NOW(),BA10),"") | BC10: =BF10 | BE10: =if(BD10<>"", if(BE10="",NOW(),BE10),"") | BG10: =if(BF10="Done", if(BG10="",NOW(),BG10),"") | BH10: 0
A11: =IF(B11="","",COUNTA($B$3:B11)) | C11: =IF(B11="","", "PDSSVP"&TEXT(COUNTA($B$3:B11),"000")) | H11: =D11 | J11: =if(I11<>"", if(J11="",NOW(),J11),"") | L11: =if(K11="Done", if(L11="",NOW(),L11),"") | M11: =IF(AND(J11<>"",L11<>""),(L11-J11)*1440,"") | N11: =IF( INT(J11)=INT(L11), IF( AND(MOD(J11,1)<TIME(12,0,0), MOD(L11,1)>TIME(12,0,0)), 60, 0 ), IF( MOD(L11,1)<=TIME(12,0,0), (INT(L11)-INT(J11))*960, (INT(L11)-INT(J11))*1020 ) ) -> 0 | O11: =(M11-N11)/60 -> 0 | P11: =S11 | R11: =if(Q11<>"", if(R11="",NOW(),R11),"") | T11: =if(S11="Done", if(T11="",NOW(),T11),"") | V11: =Y11 | X11: =if(W11<>"", if(X11="",NOW(),X11),"") | Z11: =if(Y11="Done", if(Z11="",NOW(),Z11),"") | AB11: =AE11 | AD11: =if(AC11<>"", if(AD11="",NOW(),AD11),"") | AF11: =if(AE11="Done", if(AF11="",NOW(),AF11),"") | AG11: 0 | AI11: =E11 | AK11: =if(AJ11<>"", if(AK11="",NOW(),AK11),"") | AM11: =if(AL11="Done", if(AM11="",NOW(),AM11),"") | AN11: =IF(AND(AK11<>"",AM11<>""),(AM11-AK11)*1440,"") | AO11: =IF( INT(AK11)=INT(AM11), IF( AND(MOD(AK11,1)<TIME(12,0,0), MOD(AM11,1)>TIME(12,0,0)), 60, 0 ), IF( MOD(AM11,1)<=TIME(12,0,0), (INT(AM11)-INT(AK11))*960, (INT(AM11)-INT(AK11))*1020 ) ) -> 0 | AP11: =(AN11-AO11)/60 -> 0 | AQ11: =AT11 | AS11: =if(AR11<>"", if(AS11="",NOW(),AS11),"") | AU11: =if(AT11="Done", if(AU11="",NOW(),AU11),"") | AW11: =AZ11 | AY11: =if(AX11<>"", if(AY11="",NOW(),AY11),"") | BA11: =if(AZ11="Done", if(BA11="",NOW(),BA11),"") | BC11: =BF11 | BE11: =if(BD11<>"", if(BE11="",NOW(),BE11),"") | BG11: =if(BF11="Done", if(BG11="",NOW(),BG11),"") | BH11: 0
A12: =IF(B12="","",COUNTA($B$3:B12)) | C12: =IF(B12="","", "PDSSVP"&TEXT(COUNTA($B$3:B12),"000")) | H12: =D12 | J12: =if(I12<>"", if(J12="",NOW(),J12),"") | L12: =if(K12="Done", if(L12="",NOW(),L12),"") | M12: =IF(AND(J12<>"",L12<>""),(L12-J12)*1440,"") | N12: =IF( INT(J12)=INT(L12), IF( AND(MOD(J12,1)<TIME(12,0,0), MOD(L12,1)>TIME(12,0,0)), 60, 0 ), IF( MOD(L12,1)<=TIME(12,0,0), (INT(L12)-INT(J12))*960, (INT(L12)-INT(J12))*1020 ) ) -> 0 | O12: =(M12-N12)/60 -> 0 | P12: =S12 | R12: =if(Q12<>"", if(R12="",NOW(),R12),"") | T12: =if(S12="Done", if(T12="",NOW(),T12),"") | V12: =Y12 | X12: =if(W12<>"", if(X12="",NOW(),X12),"") | Z12: =if(Y12="Done", if(Z12="",NOW(),Z12),"") | AB12: =AE12 | AD12: =if(AC12<>"", if(AD12="",NOW(),AD12),"") | AF12: =if(AE12="Done", if(AF12="",NOW(),AF12),"") | AG12: 0 | AI12: =E12 | AK12: =if(AJ12<>"", if(AK12="",NOW(),AK12),"") | AM12: =if(AL12="Done", if(AM12="",NOW(),AM12),"") | AN12: =IF(AND(AK12<>"",AM12<>""),(AM12-AK12)*1440,"") | AO12: =IF( INT(AK12)=INT(AM12), IF( AND(MOD(AK12,1)<TIME(12,0,0), MOD(AM12,1)>TIME(12,0,0)), 60, 0 ), IF( MOD(AM12,1)<=TIME(12,0,0), (INT(AM12)-INT(AK12))*960, (INT(AM12)-INT(AK12))*1020 ) ) -> 0 | AP12: =(AN12-AO12)/60 -> 0 | AQ12: =AT12 | AS12: =if(AR12<>"", if(AS12="",NOW(),AS12),"") | AU12: =if(AT12="Done", if(AU12="",NOW(),AU12),"") | AW12: =AZ12 | AY12: =if(AX12<>"", if(AY12="",NOW(),AY12),"") | BA12: =if(AZ12="Done", if(BA12="",NOW(),BA12),"") | BC12: =BF12 | BE12: =if(BD12<>"", if(BE12="",NOW(),BE12),"") | BG12: =if(BF12="Done", if(BG12="",NOW(),BG12),"") | BH12: 0
A13: =IF(B13="","",COUNTA($B$3:B13)) | C13: =IF(B13="","", "PDSSVP"&TEXT(COUNTA($B$3:B13),"000")) | H13: =D13 | J13: =if(I13<>"", if(J13="",NOW(),J13),"") | L13: =if(K13="Done", if(L13="",NOW(),L13),"") | M13: =IF(AND(J13<>"",L13<>""),(L13-J13)*1440,"") | N13: =IF( INT(J13)=INT(L13), IF( AND(MOD(J13,1)<TIME(12,0,0), MOD(L13,1)>TIME(12,0,0)), 60, 0 ), IF( MOD(L13,1)<=TIME(12,0,0), (INT(L13)-INT(J13))*960, (INT(L13)-INT(J13))*1020 ) ) -> 0 | O13: =(M13-N13)/60 -> 0 | P13: =S13 | R13: =if(Q13<>"", if(R13="",NOW(),R13),"") | T13: =if(S13="Done", if(T13="",NOW(),T13),"") | V13: =Y13 | X13: =if(W13<>"", if(X13="",NOW(),X13),"") | Z13: =if(Y13="Done", if(Z13="",NOW(),Z13),"") | AB13: =AE13 | AD13: =if(AC13<>"", if(AD13="",NOW(),AD13),"") | AF13: =if(AE13="Done", if(AF13="",NOW(),AF13),"") | AG13: 0 | AI13: =E13 | AK13: =if(AJ13<>"", if(AK13="",NOW(),AK13),"") | AM13: =if(AL13="Done", if(AM13="",NOW(),AM13),"") | AN13: =IF(AND(AK13<>"",AM13<>""),(AM13-AK13)*1440,"") | AO13: =IF( INT(AK13)=INT(AM13), IF( AND(MOD(AK13,1)<TIME(12,0,0), MOD(AM13,1)>TIME(12,0,0)), 60, 0 ), IF( MOD(AM13,1)<=TIME(12,0,0), (INT(AM13)-INT(AK13))*960, (INT(AM13)-INT(AK13))*1020 ) ) -> 0 | AP13: =(AN13-AO13)/60 -> 0 | AQ13: =AT13 | AS13: =if(AR13<>"", if(AS13="",NOW(),AS13),"") | AU13: =if(AT13="Done", if(AU13="",NOW(),AU13),"") | AW13: =AZ13 | AY13: =if(AX13<>"", if(AY13="",NOW(),AY13),"") | BA13: =if(AZ13="Done", if(BA13="",NOW(),BA13),"") | BC13: =BF13 | BE13: =if(BD13<>"", if(BE13="",NOW(),BE13),"") | BG13: =if(BF13="Done", if(BG13="",NOW(),BG13),"") | BH13: 0
A14: =IF(B14="","",COUNTA($B$3:B14)) | C14: =IF(B14="","", "PDSSVP"&TEXT(COUNTA($B$3:B14),"000")) | H14: =D14 | J14: =if(I14<>"", if(J14="",NOW(),J14),"") | L14: =if(K14="Done", if(L14="",NOW(),L14),"") | M14: =IF(AND(J14<>"",L14<>""),(L14-J14)*1440,"") | N14: =IF( INT(J14)=INT(L14), IF( AND(MOD(J14,1)<TIME(12,0,0), MOD(L14,1)>TIME(12,0,0)), 60, 0 ), IF( MOD(L14,1)<=TIME(12,0,0), (INT(L14)-INT(J14))*960, (INT(L14)-INT(J14))*1020 ) ) -> 0 | O14: =(M14-N14)/60 -> 0 | P14: =S14 | R14: =if(Q14<>"", if(R14="",NOW(),R14),"") | T14: =if(S14="Done", if(T14="",NOW(),T14),"") | V14: =Y14 | X14: =if(W14<>"", if(X14="",NOW(),X14),"") | Z14: =if(Y14="Done", if(Z14="",NOW(),Z14),"") | AB14: =AE14 | AD14: =if(AC14<>"", if(AD14="",NOW(),AD14),"") | AF14: =if(AE14="Done", if(AF14="",NOW(),AF14),"") | AG14: 0 | AI14: =E14 | AK14: =if(AJ14<>"", if(AK14="",NOW(),AK14),"") | AM14: =if(AL14="Done", if(AM14="",NOW(),AM14),"") | AN14: =IF(AND(AK14<>"",AM14<>""),(AM14-AK14)*1440,"") | AO14: =IF( INT(AK14)=INT(AM14), IF( AND(MOD(AK14,1)<TIME(12,0,0), MOD(AM14,1)>TIME(12,0,0)), 60, 0 ), IF( MOD(AM14,1)<=TIME(12,0,0), (INT(AM14)-INT(AK14))*960, (INT(AM14)-INT(AK14))*1020 ) ) -> 0 | AP14: =(AN14-AO14)/60 -> 0 | AQ14: =AT14 | AS14: =if(AR14<>"", if(AS14="",NOW(),AS14),"") | AU14: =if(AT14="Done", if(AU14="",NOW(),AU14),"") | AW14: =AZ14 | AY14: =if(AX14<>"", if(AY14="",NOW(),AY14),"") | BA14: =if(AZ14="Done", if(BA14="",NOW(),BA14),"") | BC14: =BF14 | BE14: =if(BD14<>"", if(BE14="",NOW(),BE14),"") | BG14: =if(BF14="Done", if(BG14="",NOW(),BG14),"") | BH14: 0
A15: =IF(B15="","",COUNTA($B$3:B15)) | C15: =IF(B15="","", "PDSSVP"&TEXT(COUNTA($B$3:B15),"000")) | H15: =D15 | J15: =if(I15<>"", if(J15="",NOW(),J15),"") | L15: =if(K15="Done", if(L15="",NOW(),L15),"") | M15: =IF(AND(J15<>"",L15<>""),(L15-J15)*1440,"") | N15: =IF( INT(J15)=INT(L15), IF( AND(MOD(J15,1)<TIME(12,0,0), MOD(L15,1)>TIME(12,0,0)), 60, 0 ), IF( MOD(L15,1)<=TIME(12,0,0), (INT(L15)-INT(J15))*960, (INT(L15)-INT(J15))*1020 ) ) -> 0 | O15: =(M15-N15)/60 -> 0 | P15: =S15 | R15: =if(Q15<>"", if(R15="",NOW(),R15),"") | T15: =if(S15="Done", if(T15="",NOW(),T15),"") | V15: =Y15 | X15: =if(W15<>"", if(X15="",NOW(),X15),"") | Z15: =if(Y15="Done", if(Z15="",NOW(),Z15),"") | AB15: =AE15 | AD15: =if(AC15<>"", if(AD15="",NOW(),AD15),"") | AF15: =if(AE15="Done", if(AF15="",NOW(),AF15),"") | AG15: 0 | AI15: =E15 | AK15: =if(AJ15<>"", if(AK15="",NOW(),AK15),"") | AM15: =if(AL15="Done", if(AM15="",NOW(),AM15),"") | AN15: =IF(AND(AK15<>"",AM15<>""),(AM15-AK15)*1440,"") | AO15: =IF( INT(AK15)=INT(AM15), IF( AND(MOD(AK15,1)<TIME(12,0,0), MOD(AM15,1)>TIME(12,0,0)), 60, 0 ), IF( MOD(AM15,1)<=TIME(12,0,0), (INT(AM15)-INT(AK15))*960, (INT(AM15)-INT(AK15))*1020 ) ) -> 0 | AP15: =(AN15-AO15)/60 -> 0 | AQ15: =AT15 | AS15: =if(AR15<>"", if(AS15="",NOW(),AS15),"") | AU15: =if(AT15="Done", if(AU15="",NOW(),AU15),"") | AW15: =AZ15 | AY15: =if(AX15<>"", if(AY15="",NOW(),AY15),"") | BA15: =if(AZ15="Done", if(BA15="",NOW(),BA15),"") | BC15: =BF15 | BE15: =if(BD15<>"", if(BE15="",NOW(),BE15),"") | BG15: =if(BF15="Done", if(BG15="",NOW(),BG15),"") | BH15: 0
A16: =IF(B16="","",COUNTA($B$3:B16)) | C16: =IF(B16="","", "PDSSVP"&TEXT(COUNTA($B$3:B16),"000")) | H16: =D16 | J16: =if(I16<>"", if(J16="",NOW(),J16),"") | L16: =if(K16="Done", if(L16="",NOW(),L16),"") | M16: =IF(AND(J16<>"",L16<>""),(L16-J16)*1440,"") | N16: =IF( INT(J16)=INT(L16), IF( AND(MOD(J16,1)<TIME(12,0,0), MOD(L16,1)>TIME(12,0,0)), 60, 0 ), IF( MOD(L16,1)<=TIME(12,0,0), (INT(L16)-INT(J16))*960, (INT(L16)-INT(J16))*1020 ) ) -> 0 | O16: =(M16-N16)/60 -> 0 | P16: =S16 | R16: =if(Q16<>"", if(R16="",NOW(),R16),"") | T16: =if(S16="Done", if(T16="",NOW(),T16),"") | V16: =Y16 | X16: =if(W16<>"", if(X16="",NOW(),X16),"") | Z16: =if(Y16="Done", if(Z16="",NOW(),Z16),"") | AB16: =AE16 | AD16: =if(AC16<>"", if(AD16="",NOW(),AD16),"") | AF16: =if(AE16="Done", if(AF16="",NOW(),AF16),"") | AG16: 0 | AI16: =E16 | AK16: =if(AJ16<>"", if(AK16="",NOW(),AK16),"") | AM16: =if(AL16="Done", if(AM16="",NOW(),AM16),"") | AN16: =IF(AND(AK16<>"",AM16<>""),(AM16-AK16)*1440,"") | AO16: =IF( INT(AK16)=INT(AM16), IF( AND(MOD(AK16,1)<TIME(12,0,0), MOD(AM16,1)>TIME(12,0,0)), 60, 0 ), IF( MOD(AM16,1)<=TIME(12,0,0), (INT(AM16)-INT(AK16))*960, (INT(AM16)-INT(AK16))*1020 ) ) -> 0 | AP16: =(AN16-AO16)/60 -> 0 | AQ16: =AT16 | AS16: =if(AR16<>"", if(AS16="",NOW(),AS16),"") | AU16: =if(AT16="Done", if(AU16="",NOW(),AU16),"") | AW16: =AZ16 | AY16: =if(AX16<>"", if(AY16="",NOW(),AY16),"") | BA16: =if(AZ16="Done", if(BA16="",NOW(),BA16),"") | BC16: =BF16 | BE16: =if(BD16<>"", if(BE16="",NOW(),BE16),"") | BG16: =if(BF16="Done", if(BG16="",NOW(),BG16),"") | BH16: 0
A17: =IF(B17="","",COUNTA($B$3:B17)) | C17: =IF(B17="","", "PDSSVP"&TEXT(COUNTA($B$3:B17),"000")) | H17: =D17 | J17: =if(I17<>"", if(J17="",NOW(),J17),"") | L17: =if(K17="Done", if(L17="",NOW(),L17),"") | M17: =IF(AND(J17<>"",L17<>""),(L17-J17)*1440,"") | N17: =IF( INT(J17)=INT(L17), IF( AND(MOD(J17,1)<TIME(12,0,0), MOD(L17,1)>TIME(12,0,0)), 60, 0 ), IF( MOD(L17,1)<=TIME(12,0,0), (INT(L17)-INT(J17))*960, (INT(L17)-INT(J17))*1020 ) ) -> 0 | O17: =(M17-N17)/60 -> 0 | P17: =S17 | R17: =if(Q17<>"", if(R17="",NOW(),R17),"") | T17: =if(S17="Done", if(T17="",NOW(),T17),"") | V17: =Y17 | X17: =if(W17<>"", if(X17="",NOW(),X17),"") | Z17: =if(Y17="Done", if(Z17="",NOW(),Z17),"") | AB17: =AE17 | AD17: =if(AC17<>"", if(AD17="",NOW(),AD17),"") | AF17: =if(AE17="Done", if(AF17="",NOW(),AF17),"") | AG17: 0 | AI17: =E17 | AK17: =if(AJ17<>"", if(AK17="",NOW(),AK17),"") | AM17: =if(AL17="Done", if(AM17="",NOW(),AM17),"") | AN17: =IF(AND(AK17<>"",AM17<>""),(AM17-AK17)*1440,"") | AO17: =IF( INT(AK17)=INT(AM17), IF( AND(MOD(AK17,1)<TIME(12,0,0), MOD(AM17,1)>TIME(12,0,0)), 60, 0 ), IF( MOD(AM17,1)<=TIME(12,0,0), (INT(AM17)-INT(AK17))*960, (INT(AM17)-INT(AK17))*1020 ) ) -> 0 | AP17: =(AN17-AO17)/60 -> 0 | AQ17: =AT17 | AS17: =if(AR17<>"", if(AS17="",NOW(),AS17),"") | AU17: =if(AT17="Done", if(AU17="",NOW(),AU17),"") | AW17: =AZ17 | AY17: =if(AX17<>"", if(AY17="",NOW(),AY17),"") | BA17: =if(AZ17="Done", if(BA17="",NOW(),BA17),"") | BC17: =BF17 | BE17: =if(BD17<>"", if(BE17="",NOW(),BE17),"") | BG17: =if(BF17="Done", if(BG17="",NOW(),BG17),"") | BH17: 0
A18: =IF(B18="","",COUNTA($B$3:B18)) | C18: =IF(B18="","", "PDSSVP"&TEXT(COUNTA($B$3:B18),"000")) | H18: =D18 | J18: =if(I18<>"", if(J18="",NOW(),J18),"") | L18: =if(K18="Done", if(L18="",NOW(),L18),"") | M18: =IF(AND(J18<>"",L18<>""),(L18-J18)*1440,"") | N18: =IF( INT(J18)=INT(L18), IF( AND(MOD(J18,1)<TIME(12,0,0), MOD(L18,1)>TIME(12,0,0)), 60, 0 ), IF( MOD(L18,1)<=TIME(12,0,0), (INT(L18)-INT(J18))*960, (INT(L18)-INT(J18))*1020 ) ) -> 0 | O18: =(M18-N18)/60 -> 0 | P18: =S18 | R18: =if(Q18<>"", if(R18="",NOW(),R18),"") | T18: =if(S18="Done", if(T18="",NOW(),T18),"") | V18: =Y18 | X18: =if(W18<>"", if(X18="",NOW(),X18),"") | Z18: =if(Y18="Done", if(Z18="",NOW(),Z18),"") | AB18: =AE18 | AD18: =if(AC18<>"", if(AD18="",NOW(),AD18),"") | AF18: =if(AE18="Done", if(AF18="",NOW(),AF18),"") | AG18: 0 | AI18: =E18 | AK18: =if(AJ18<>"", if(AK18="",NOW(),AK18),"") | AM18: =if(AL18="Done", if(AM18="",NOW(),AM18),"") | AN18: =IF(AND(AK18<>"",AM18<>""),(AM18-AK18)*1440,"") | AO18: =IF( INT(AK18)=INT(AM18), IF( AND(MOD(AK18,1)<TIME(12,0,0), MOD(AM18,1)>TIME(12,0,0)), 60, 0 ), IF( MOD(AM18,1)<=TIME(12,0,0), (INT(AM18)-INT(AK18))*960, (INT(AM18)-INT(AK18))*1020 ) ) -> 0 | AP18: =(AN18-AO18)/60 -> 0 | AQ18: =AT18 | AS18: =if(AR18<>"", if(AS18="",NOW(),AS18),"") | AU18: =if(AT18="Done", if(AU18="",NOW(),AU18),"") | AW18: =AZ18 | AY18: =if(AX18<>"", if(AY18="",NOW(),AY18),"") | BA18: =if(AZ18="Done", if(BA18="",NOW(),BA18),"") | BC18: =BF18 | BE18: =if(BD18<>"", if(BE18="",NOW(),BE18),"") | BG18: =if(BF18="Done", if(BG18="",NOW(),BG18),"") | BH18: 0
A19: =IF(B19="","",COUNTA($B$3:B19)) | C19: =IF(B19="","", "PDSSVP"&TEXT(COUNTA($B$3:B19),"000")) | H19: =D19 | J19: =if(I19<>"", if(J19="",NOW(),J19),"") | L19: =if(K19="Done", if(L19="",NOW(),L19),"") | M19: =IF(AND(J19<>"",L19<>""),(L19-J19)*1440,"") | N19: =IF( INT(J19)=INT(L19), IF( AND(MOD(J19,1)<TIME(12,0,0), MOD(L19,1)>TIME(12,0,0)), 60, 0 ), IF( MOD(L19,1)<=TIME(12,0,0), (INT(L19)-INT(J19))*960, (INT(L19)-INT(J19))*1020 ) ) -> 0 | O19: =(M19-N19)/60 -> 0 | P19: =S19 | R19: =if(Q19<>"", if(R19="",NOW(),R19),"") | T19: =if(S19="Done", if(T19="",NOW(),T19),"") | V19: =Y19 | X19: =if(W19<>"", if(X19="",NOW(),X19),"") | Z19: =if(Y19="Done", if(Z19="",NOW(),Z19),"") | AB19: =AE19 | AD19: =if(AC19<>"", if(AD19="",NOW(),AD19),"") | AF19: =if(AE19="Done", if(AF19="",NOW(),AF19),"") | AG19: 0 | AI19: =E19 | AK19: =if(AJ19<>"", if(AK19="",NOW(),AK19),"") | AM19: =if(AL19="Done", if(AM19="",NOW(),AM19),"") | AN19: =IF(AND(AK19<>"",AM19<>""),(AM19-AK19)*1440,"") | AO19: =IF( INT(AK19)=INT(AM19), IF( AND(MOD(AK19,1)<TIME(12,0,0), MOD(AM19,1)>TIME(12,0,0)), 60, 0 ), IF( MOD(AM19,1)<=TIME(12,0,0), (INT(AM19)-INT(AK19))*960, (INT(AM19)-INT(AK19))*1020 ) ) -> 0 | AP19: =(AN19-AO19)/60 -> 0 | AQ19: =AT19 | AS19: =if(AR19<>"", if(AS19="",NOW(),AS19),"") | AU19: =if(AT19="Done", if(AU19="",NOW(),AU19),"") | AW19: =AZ19 | AY19: =if(AX19<>"", if(AY19="",NOW(),AY19),"") | BA19: =if(AZ19="Done", if(BA19="",NOW(),BA19),"") | BC19: =BF19 | BE19: =if(BD19<>"", if(BE19="",NOW(),BE19),"") | BG19: =if(BF19="Done", if(BG19="",NOW(),BG19),"") | BH19: 0
A20: =IF(B20="","",COUNTA($B$3:B20)) | C20: =IF(B20="","", "PDSSVP"&TEXT(COUNTA($B$3:B20),"000")) | H20: =D20 | J20: =if(I20<>"", if(J20="",NOW(),J20),"") | L20: =if(K20="Done", if(L20="",NOW(),L20),"") | M20: =IF(AND(J20<>"",L20<>""),(L20-J20)*1440,"") | N20: =IF( INT(J20)=INT(L20), IF( AND(MOD(J20,1)<TIME(12,0,0), MOD(L20,1)>TIME(12,0,0)), 60, 0 ), IF( MOD(L20,1)<=TIME(12,0,0), (INT(L20)-INT(J20))*960, (INT(L20)-INT(J20))*1020 ) ) -> 0 | O20: =(M20-N20)/60 -> 0 | P20: =S20 | R20: =if(Q20<>"", if(R20="",NOW(),R20),"") | T20: =if(S20="Done", if(T20="",NOW(),T20),"") | V20: =Y20 | X20: =if(W20<>"", if(X20="",NOW(),X20),"") | Z20: =if(Y20="Done", if(Z20="",NOW(),Z20),"") | AB20: =AE20 | AD20: =if(AC20<>"", if(AD20="",NOW(),AD20),"") | AF20: =if(AE20="Done", if(AF20="",NOW(),AF20),"") | AG20: 0 | AI20: =E20 | AK20: =if(AJ20<>"", if(AK20="",NOW(),AK20),"") | AM20: =if(AL20="Done", if(AM20="",NOW(),AM20),"") | AN20: =IF(AND(AK20<>"",AM20<>""),(AM20-AK20)*1440,"") | AO20: =IF( INT(AK20)=INT(AM20), IF( AND(MOD(AK20,1)<TIME(12,0,0), MOD(AM20,1)>TIME(12,0,0)), 60, 0 ), IF( MOD(AM20,1)<=TIME(12,0,0), (INT(AM20)-INT(AK20))*960, (INT(AM20)-INT(AK20))*1020 ) ) -> 0 | AP20: =(AN20-AO20)/60 -> 0 | AQ20: =AT20 | AS20: =if(AR20<>"", if(AS20="",NOW(),AS20),"") | AU20: =if(AT20="Done", if(AU20="",NOW(),AU20),"") | AW20: =AZ20 | AY20: =if(AX20<>"", if(AY20="",NOW(),AY20),"") | BA20: =if(AZ20="Done", if(BA20="",NOW(),BA20),"") | BC20: =BF20 | BE20: =if(BD20<>"", if(BE20="",NOW(),BE20),"") | BG20: =if(BF20="Done", if(BG20="",NOW(),BG20),"") | BH20: 0
... A30: =IF(B30="","",COUNTA($B$3:B30)) | C30: =IF(B30="","", "PDSSVP"&TEXT(COUNTA($B$3:B30),"000")) | H30: =D30 | J30: =if(I30<>"", if(J30="",NOW(),J30),"") | L30: =if(K30="Done", if(L30="",NOW(),L30),"") | M30: =IF(AND(J30<>"",L30<>""),(L30-J30)*1440,"") | N30: =IF( INT(J30)=INT(L30), IF( AND(MOD(J30,1)<TIME(12,0,0), MOD(L30,1)>TIME(12,0,0)), 60, 0 ), IF( MOD(L30,1)<=TIME(12,0,0), (INT(L30)-INT(J30))*960, (INT(L30)-INT(J30))*1020 ) ) -> 0 | O30: =(M30-N30)/60 -> 0 | P30: =S30 | R30: =if(Q30<>"", if(R30="",NOW(),R30),"") | T30: =if(S30="Done", if(T30="",NOW(),T30),"") | V30: =Y30 | X30: =if(W30<>"", if(X30="",NOW(),X30),"") | Z30: =if(Y30="Done", if(Z30="",NOW(),Z30),"") | AB30: =AE30 | AD30: =if(AC30<>"", if(AD30="",NOW(),AD30),"") | AF30: =if(AE30="Done", if(AF30="",NOW(),AF30),"") | AG30: 0 | AI30: =E30 | AK30: =if(AJ30<>"", if(AK30="",NOW(),AK30),"") | AM30: =if(AL30="Done", if(AM30="",NOW(),AM30),"") | AN30: =IF(AND(AK30<>"",AM30<>""),(AM30-AK30)*1440,"") | AO30: =IF( INT(AK30)=INT(AM30), IF( AND(MOD(AK30,1)<TIME(12,0,0), MOD(AM30,1)>TIME(12,0,0)), 60, 0 ), IF( MOD(AM30,1)<=TIME(12,0,0), (INT(AM30)-INT(AK30))*960, (INT(AM30)-INT(AK30))*1020 ) ) -> 0 | AP30: =(AN30-AO30)/60 -> 0 | AQ30: =AT30 | AS30: =if(AR30<>"", if(AS30="",NOW(),AS30),"") | AU30: =if(AT30="Done", if(AU30="",NOW(),AU30),"") | AW30: =AZ30 | AY30: =if(AX30<>"", if(AY30="",NOW(),AY30),"") | BA30: =if(AZ30="Done", if(BA30="",NOW(),BA30),"") | BC30: =BF30 | BE30: =if(BD30<>"", if(BE30="",NOW(),BE30),"") | BG30: =if(BF30="Done", if(BG30="",NOW(),BG30),"") | BH30: 0

Sheet VISUAL BRIEF - CA
A1: Scenario List | D1: Klasifikasi | I1: Visual Brief | P1: Revision 1 | Q1: Revision 1 | V1: Revision 2 | W1: Revision 2 | AB1: QC Concept Visual Brief | AC1: Quality Check Description | AJ1: Storyboard Tactical | AQ1: Revision 1 | AR1: Revision 1 | AW1: Revision 2 | AX1: Revision 2 | BC1: QC Storyboard Tactical | BD1: Quality Visual Planning
A2: No | B2: Scenario Name | C2: Scenario Code | D2: Level Visual Brief | E2: Level Storyboard Tactical | F2: PIC Penentu | H2: Level | I2: PIC | J2: Start Time | K2: Status | L2: Finish Time | M2: Duration (Minute) | N2: Duration Pause (Minute) | O2: Duration Final (Hour) | Q2: PIC Rev 1 | R2: Start Time | S2: Status | T2: Finish Time | U2: Revision Percentage | W2: PIC Rev 2 | X2: Start Time | Y2: Status | Z2: Finish Time | AA2: Revision Percentage | AC2: PIC QC | AD2: Start Time | AE2: Status | AF2: Finish Time | AG2: QC Count | AI2: Level | AJ2: PIC | AK2: Start Time | AL2: Status | AM2: Finish Time | AN2: Duration (Minute) | AO2: Duration Pause (Minute) | AP2: Duration Final (Hour) | AR2: PIC Rev 1 | AS2: Start Time | AT2: Status | AU2: Finish Time | AV2: Revision Percentage | AX2: PIC Rev 2 | AY2: Start Time | AZ2: Status | BA2: Finish Time | BB2: Revision Percentage | BD2: PIC QC | BE2: Start Time | BF2: Status | BG2: Finish Time | BH2: QC Count
A3: =IF(B3="","",COUNTA($B$3:B3)) -> 1 | B3: The Fatal Funnel (Penggerebekan Gudang Narkoba) | C3: =IF(B3="","", "PDSSVB"&TEXT(COUNTA($B$3:B3),"000")) -> PDSSVB001 | D3: 2 | E3: 2 | F3: Dian Hasanudin | H3: =D3 -> 2 | I3: Dian Hasanudin | J3: 46153.592 | K3: Done | L3: 46153.661 | M3: =IF(AND(J3<>"",L3<>""),(L3-J3)*1440,"") -> 100 | N3: =IF( INT(J3)=INT(L3), IF( AND(MOD(J3,1)<TIME(12,0,0), MOD(L3,1)>TIME(12,0,0)), 60, 0 ), IF( MOD(L3,1)<=TIME(12,0,0), (INT(L3)-INT(J3))*960, (INT(L3)-INT(J3))*1020 ) ) -> 0 | O3: =(M3-N3)/60 -> 1.6666667 | P3: =S3 | R3: =if(Q3<>"", if(R3="",NOW(),R3),"") | T3: =if(S3="Done", if(T3="",NOW(),T3),"") | V3: =Y3 | X3: =if(W3<>"", if(X3="",NOW(),X3),"") | Z3: =if(Y3="Done", if(Z3="",NOW(),Z3),"") | AB3: =AE3 -> Done | AC3: Egi Dwi Septian | AD3: =if(AC3<>"", if(AD3="",NOW(),AD3),"") -> 46157.652 | AE3: Done | AF3: =if(AE3="Done", if(AF3="",NOW(),AF3),"") -> 46157.659 | AG3: 1 | AI3: =E3 -> 2 | AJ3: Faaidh Abdurrazzak | AK3: =if(AJ3<>"", if(AK3="",NOW(),AK3),"") -> 46160.486 | AL3: Done | AM3: =if(AL3="Done", if(AM3="",NOW(),AM3),"") -> 46161.445 | AN3: =IF(AND(AK3<>"",AM3<>""),(AM3-AK3)*1440,"") -> 1380.4115 | AO3: =IF( INT(AK3)=INT(AM3), IF( AND(MOD(AK3,1)<TIME(12,0,0), MOD(AM3,1)>TIME(12,0,0)), 60, 0 ), IF( MOD(AM3,1)<=TIME(12,0,0), (INT(AM3)-INT(AK3))*960, (INT(AM3)-INT(AK3))*1020 ) ) -> 960 | AP3: =(AN3-AO3)/60 -> 7.0068575 | AQ3: =AT3 | AS3: =if(AR3<>"", if(AS3="",NOW(),AS3),"") | AU3: =if(AT3="Done", if(AU3="",NOW(),AU3),"") | AW3: =AZ3 | AY3: =if(AX3<>"", if(AY3="",NOW(),AY3),"") | BA3: =if(AZ3="Done", if(BA3="",NOW(),BA3),"") | BC3: =BF3 | BE3: =if(BD3<>"", if(BE3="",NOW(),BE3),"") | BG3: =if(BF3="Done", if(BG3="",NOW(),BG3),"") | BH3: 0
A4: =IF(B4="","",COUNTA($B$3:B4)) -> 2 | B4: The Wrong Door (Kompleks Apartemen Padat) | C4: =IF(B4="","", "PDSSVB"&TEXT(COUNTA($B$3:B4),"000")) -> PDSSVB002 | D4: 2 | E4: 2 | F4: Dian Hasanudin | H4: =D4 -> 2 | I4: Siti Anisah Rhamadani | J4: =if(I4<>"", if(J4="",NOW(),J4),"") -> 46154.558 | K4: Done | L4: =if(K4="Done", if(L4="",NOW(),L4),"") -> 46154.624 | M4: =IF(AND(J4<>"",L4<>""),(L4-J4)*1440,"") -> 94.976683 | N4: =IF( INT(J4)=INT(L4), IF( AND(MOD(J4,1)<TIME(12,0,0), MOD(L4,1)>TIME(12,0,0)), 60, 0 ), IF( MOD(L4,1)<=TIME(12,0,0), (INT(L4)-INT(J4))*960, (INT(L4)-INT(J4))*1020 ) ) -> 0 | O4: =(M4-N4)/60 -> 1.5829447 | P4: =S4 | R4: =if(Q4<>"", if(R4="",NOW(),R4),"") | T4: =if(S4="Done", if(T4="",NOW(),T4),"") | V4: =Y4 | X4: =if(W4<>"", if(X4="",NOW(),X4),"") | Z4: =if(Y4="Done", if(Z4="",NOW(),Z4),"") | AB4: =AE4 -> Done | AC4: Dian Hasanudin | AD4: =if(AC4<>"", if(AD4="",NOW(),AD4),"") -> 46160.606 | AE4: Done | AF4: =if(AE4="Done", if(AF4="",NOW(),AF4),"") -> 46160.612 | AG4: 1 | AI4: =E4 -> 2 | AJ4: Muhamad Ade Saputra | AK4: =if(AJ4<>"", if(AK4="",NOW(),AK4),"") -> 46160.55 | AL4: Done | AM4: =if(AL4="Done", if(AM4="",NOW(),AM4),"") -> 46161.657 | AN4: =IF(AND(AK4<>"",AM4<>""),(AM4-AK4)*1440,"") -> 1593.6075 | AO4: =IF( INT(AK4)=INT(AM4), IF( AND(MOD(AK4,1)<TIME(12,0,0), MOD(AM4,1)>TIME(12,0,0)), 60, 0 ), IF( MOD(AM4,1)<=TIME(12,0,0), (INT(AM4)-INT(AK4))*960, (INT(AM4)-INT(AK4))*1020 ) ) -> 1020 | AP4: =(AN4-AO4)/60 -> 9.5601256 | AQ4: =AT4 | AS4: =if(AR4<>"", if(AS4="",NOW(),AS4),"") | AU4: =if(AT4="Done", if(AU4="",NOW(),AU4),"") | AW4: =AZ4 | AY4: =if(AX4<>"", if(AY4="",NOW(),AY4),"") | BA4: =if(AZ4="Done", if(BA4="",NOW(),BA4),"") | BC4: =BF4 | BE4: =if(BD4<>"", if(BE4="",NOW(),BE4),"") | BG4: =if(BF4="Done", if(BG4="",NOW(),BG4),"") | BH4: 0
A5: =IF(B5="","",COUNTA($B$3:B5)) -> 3 | B5: First Light (Operasi Cakrawala) | C5: =IF(B5="","", "PDSSVB"&TEXT(COUNTA($B$3:B5),"000")) -> PDSSVB003 | D5: 2 | E5: 2 | F5: Dian Hasanudin | H5: =D5 -> 2 | I5: Siti Anisah Rhamadani | J5: =if(I5<>"", if(J5="",NOW(),J5),"") -> 46154.624 | K5: Done | L5: =if(K5="Done", if(L5="",NOW(),L5),"") -> 46154.685 | M5: =IF(AND(J5<>"",L5<>""),(L5-J5)*1440,"") -> 88.230317 | N5: =IF( INT(J5)=INT(L5), IF( AND(MOD(J5,1)<TIME(12,0,0), MOD(L5,1)>TIME(12,0,0)), 60, 0 ), IF( MOD(L5,1)<=TIME(12,0,0), (INT(L5)-INT(J5))*960, (INT(L5)-INT(J5))*1020 ) ) -> 0 | O5: =(M5-N5)/60 -> 1.4705053 | P5: =S5 | R5: =if(Q5<>"", if(R5="",NOW(),R5),"") | T5: =if(S5="Done", if(T5="",NOW(),T5),"") | V5: =Y5 | X5: =if(W5<>"", if(X5="",NOW(),X5),"") | Z5: =if(Y5="Done", if(Z5="",NOW(),Z5),"") | AB5: =AE5 -> Done | AC5: Dian Hasanudin | AD5: =if(AC5<>"", if(AD5="",NOW(),AD5),"") -> 46161.482 | AE5: Done | AF5: =if(AE5="Done", if(AF5="",NOW(),AF5),"") -> 46161.491 | AG5: 1 | AI5: =E5 -> 2 | AJ5: Faaidh Abdurrazzak | AK5: =if(AJ5<>"", if(AK5="",NOW(),AK5),"") -> 46161.481 | AL5: Done | AM5: =if(AL5="Done", if(AM5="",NOW(),AM5),"") -> 46162.622 | AN5: =IF(AND(AK5<>"",AM5<>""),(AM5-AK5)*1440,"") -> 1643.0473 | AO5: =IF( INT(AK5)=INT(AM5), IF( AND(MOD(AK5,1)<TIME(12,0,0), MOD(AM5,1)>TIME(12,0,0)), 60, 0 ), IF( MOD(AM5,1)<=TIME(12,0,0), (INT(AM5)-INT(AK5))*960, (INT(AM5)-INT(AK5))*1020 ) ) -> 1020 | AP5: =(AN5-AO5)/60 -> 10.384121 | AQ5: =AT5 | AS5: =if(AR5<>"", if(AS5="",NOW(),AS5),"") | AU5: =if(AT5="Done", if(AU5="",NOW(),AU5),"") | AW5: =AZ5 | AY5: =if(AX5<>"", if(AY5="",NOW(),AY5),"") | BA5: =if(AZ5="Done", if(BA5="",NOW(),BA5),"") | BC5: =BF5 | BE5: =if(BD5<>"", if(BE5="",NOW(),BE5),"") | BG5: =if(BF5="Done", if(BG5="",NOW(),BG5),"") | BH5: 0
A6: =IF(B6="","",COUNTA($B$3:B6)) -> 4 | B6: Skyjack Crisis (Pembajakan Pesawat Komersial) | C6: =IF(B6="","", "PDSSVB"&TEXT(COUNTA($B$3:B6),"000")) -> PDSSVB004 | D6: 2 | E6: 2 | F6: Dian Hasanudin | H6: =D6 -> 2 | I6: Siti Anisah Rhamadani | J6: =if(I6<>"", if(J6="",NOW(),J6),"") -> 46155.377 | K6: Done | L6: =if(K6="Done", if(L6="",NOW(),L6),"") -> 46155.416 | M6: =IF(AND(J6<>"",L6<>""),(L6-J6)*1440,"") -> 55.809767 | N6: =IF( INT(J6)=INT(L6), IF( AND(MOD(J6,1)<TIME(12,0,0), MOD(L6,1)>TIME(12,0,0)), 60, 0 ), IF( MOD(L6,1)<=TIME(12,0,0), (INT(L6)-INT(J6))*960, (INT(L6)-INT(J6))*1020 ) ) -> 0 | O6: =(M6-N6)/60 -> 0.93016278 | P6: =S6 | R6: =if(Q6<>"", if(R6="",NOW(),R6),"") | T6: =if(S6="Done", if(T6="",NOW(),T6),"") | V6: =Y6 | X6: =if(W6<>"", if(X6="",NOW(),X6),"") | Z6: =if(Y6="Done", if(Z6="",NOW(),Z6),"") | AB6: =AE6 -> Done | AC6: Dian Hasanudin | AD6: =if(AC6<>"", if(AD6="",NOW(),AD6),"") -> 46161.491 | AE6: Done | AF6: =if(AE6="Done", if(AF6="",NOW(),AF6),"") -> 46161.499 | AG6: 1 | AI6: =E6 -> 2 | AJ6: Faaidh Abdurrazzak | AK6: =if(AJ6<>"", if(AK6="",NOW(),AK6),"") -> 46167.391 | AL6: Done | AM6: =if(AL6="Done", if(AM6="",NOW(),AM6),"") -> 46167.58 | AN6: =IF(AND(AK6<>"",AM6<>""),(AM6-AK6)*1440,"") -> 272.45502 | AO6: =IF( INT(AK6)=INT(AM6), IF( AND(MOD(AK6,1)<TIME(12,0,0), MOD(AM6,1)>TIME(12,0,0)), 60, 0 ), IF( MOD(AM6,1)<=TIME(12,0,0), (INT(AM6)-INT(AK6))*960, (INT(AM6)-INT(AK6))*1020 ) ) -> 60 | AP6: =(AN6-AO6)/60 -> 3.5409169 | AQ6: =AT6 | AS6: =if(AR6<>"", if(AS6="",NOW(),AS6),"") | AU6: =if(AT6="Done", if(AU6="",NOW(),AU6),"") | AW6: =AZ6 | AY6: =if(AX6<>"", if(AY6="",NOW(),AY6),"") | BA6: =if(AZ6="Done", if(BA6="",NOW(),BA6),"") | BC6: =BF6 | BE6: =if(BD6<>"", if(BE6="",NOW(),BE6),"") | BG6: =if(BF6="Done", if(BG6="",NOW(),BG6),"") | BH6: 0
A7: =IF(B7="","",COUNTA($B$3:B7)) -> 5 | B7: Human Shield (Perampokan Bank) | C7: =IF(B7="","", "PDSSVB"&TEXT(COUNTA($B$3:B7),"000")) -> PDSSVB005 | D7: 2 | E7: 2 | F7: Dian Hasanudin | H7: =D7 -> 2 | I7: Siti Anisah Rhamadani | J7: =if(I7<>"", if(J7="",NOW(),J7),"") -> 46155.416 | K7: Done | L7: =if(K7="Done", if(L7="",NOW(),L7),"") -> 46155.613 | M7: =IF(AND(J7<>"",L7<>""),(L7-J7)*1440,"") -> 284.10613 | N7: =IF( INT(J7)=INT(L7), IF( AND(MOD(J7,1)<TIME(12,0,0), MOD(L7,1)>TIME(12,0,0)), 60, 0 ), IF( MOD(L7,1)<=TIME(12,0,0), (INT(L7)-INT(J7))*960, (INT(L7)-INT(J7))*1020 ) ) -> 60 | O7: =(M7-N7)/60 -> 3.7351022 | P7: =S7 | R7: =if(Q7<>"", if(R7="",NOW(),R7),"") | T7: =if(S7="Done", if(T7="",NOW(),T7),"") | V7: =Y7 | X7: =if(W7<>"", if(X7="",NOW(),X7),"") | Z7: =if(Y7="Done", if(Z7="",NOW(),Z7),"") | AB7: =AE7 -> Done | AC7: Dian Hasanudin | AD7: =if(AC7<>"", if(AD7="",NOW(),AD7),"") -> 46161.66 | AE7: Done | AF7: =if(AE7="Done", if(AF7="",NOW(),AF7),"") -> 46161.704 | AG7: 1 | AI7: =E7 -> 2 | AJ7: Muhamad Ade Saputra | AK7: =if(AJ7<>"", if(AK7="",NOW(),AK7),"") -> 46161.657 | AL7: Done | AM7: =if(AL7="Done", if(AM7="",NOW(),AM7),"") -> 46162.667 | AN7: =IF(AND(AK7<>"",AM7<>""),(AM7-AK7)*1440,"") -> 1453.7265 | AO7: =IF( INT(AK7)=INT(AM7), IF( AND(MOD(AK7,1)<TIME(12,0,0), MOD(AM7,1)>TIME(12,0,0)), 60, 0 ), IF( MOD(AM7,1)<=TIME(12,0,0), (INT(AM7)-INT(AK7))*960, (INT(AM7)-INT(AK7))*1020 ) ) -> 1020 | AP7: =(AN7-AO7)/60 -> 7.228775 | AQ7: =AT7 | AS7: =if(AR7<>"", if(AS7="",NOW(),AS7),"") | AU7: =if(AT7="Done", if(AU7="",NOW(),AU7),"") | AW7: =AZ7 | AY7: =if(AX7<>"", if(AY7="",NOW(),AY7),"") | BA7: =if(AZ7="Done", if(BA7="",NOW(),BA7),"") | BC7: =BF7 | BE7: =if(BD7<>"", if(BE7="",NOW(),BE7),"") | BG7: =if(BF7="Done", if(BG7="",NOW(),BG7),"") | BH7: 0
A8: =IF(B8="","",COUNTA($B$3:B8)) -> 6 | B8: The Blind Corner (Penyisiran Lorong Sempit) | C8: =IF(B8="","", "PDSSVB"&TEXT(COUNTA($B$3:B8),"000")) -> PDSSVB006 | D8: 2 | E8: 2 | F8: Dian Hasanudin | H8: =D8 -> 2 | I8: Siti Anisah Rhamadani | J8: =if(I8<>"", if(J8="",NOW(),J8),"") -> 46155.613 | K8: Done | L8: =if(K8="Done", if(L8="",NOW(),L8),"") -> 46155.613 | M8: =IF(AND(J8<>"",L8<>""),(L8-J8)*1440,"") -> 0 | N8: =IF( INT(J8)=INT(L8), IF( AND(MOD(J8,1)<TIME(12,0,0), MOD(L8,1)>TIME(12,0,0)), 60, 0 ), IF( MOD(L8,1)<=TIME(12,0,0), (INT(L8)-INT(J8))*960, (INT(L8)-INT(J8))*1020 ) ) -> 0 | O8: =(M8-N8)/60 -> 0 | P8: =S8 | R8: =if(Q8<>"", if(R8="",NOW(),R8),"") | T8: =if(S8="Done", if(T8="",NOW(),T8),"") | V8: =Y8 | X8: =if(W8<>"", if(X8="",NOW(),X8),"") | Z8: =if(Y8="Done", if(Z8="",NOW(),Z8),"") | AB8: =AE8 -> Done | AC8: Dian Hasanudin | AD8: =if(AC8<>"", if(AD8="",NOW(),AD8),"") -> 46162.622 | AE8: Done | AF8: =if(AE8="Done", if(AF8="",NOW(),AF8),"") -> 46162.651 | AG8: 1 | AI8: =E8 -> 2 | AJ8: Muhamad Ade Saputra | AK8: =if(AJ8<>"", if(AK8="",NOW(),AK8),"") -> 46162.667 | AL8: Done | AM8: =if(AL8="Done", if(AM8="",NOW(),AM8),"") -> 46163.682 | AN8: =IF(AND(AK8<>"",AM8<>""),(AM8-AK8)*1440,"") -> 1462.017 | AO8: =IF( INT(AK8)=INT(AM8), IF( AND(MOD(AK8,1)<TIME(12,0,0), MOD(AM8,1)>TIME(12,0,0)), 60, 0 ), IF( MOD(AM8,1)<=TIME(12,0,0), (INT(AM8)-INT(AK8))*960, (INT(AM8)-INT(AK8))*1020 ) ) -> 1020 | AP8: =(AN8-AO8)/60 -> 7.3669503 | AQ8: =AT8 | AS8: =if(AR8<>"", if(AS8="",NOW(),AS8),"") | AU8: =if(AT8="Done", if(AU8="",NOW(),AU8),"") | AW8: =AZ8 | AY8: =if(AX8<>"", if(AY8="",NOW(),AY8),"") | BA8: =if(AZ8="Done", if(BA8="",NOW(),BA8),"") | BC8: =BF8 | BE8: =if(BD8<>"", if(BE8="",NOW(),BE8),"") | BG8: =if(BF8="Done", if(BG8="",NOW(),BG8),"") | BH8: 0
A9: =IF(B9="","",COUNTA($B$3:B9)) -> 7 | B9: The Executive Transport (Penyergapan Konvoi) | C9: =IF(B9="","", "PDSSVB"&TEXT(COUNTA($B$3:B9),"000")) -> PDSSVB007 | D9: 2 | E9: 2 | F9: Dian Hasanudin | H9: =D9 -> 2 | I9: Siti Anisah Rhamadani | J9: =if(I9<>"", if(J9="",NOW(),J9),"") -> 46155.613 | K9: Done | L9: =if(K9="Done", if(L9="",NOW(),L9),"") -> 46155.613 | M9: =IF(AND(J9<>"",L9<>""),(L9-J9)*1440,"") -> 0 | N9: =IF( INT(J9)=INT(L9), IF( AND(MOD(J9,1)<TIME(12,0,0), MOD(L9,1)>TIME(12,0,0)), 60, 0 ), IF( MOD(L9,1)<=TIME(12,0,0), (INT(L9)-INT(J9))*960, (INT(L9)-INT(J9))*1020 ) ) -> 0 | O9: =(M9-N9)/60 -> 0 | P9: =S9 | R9: =if(Q9<>"", if(R9="",NOW(),R9),"") | T9: =if(S9="Done", if(T9="",NOW(),T9),"") | V9: =Y9 | X9: =if(W9<>"", if(X9="",NOW(),X9),"") | Z9: =if(Y9="Done", if(Z9="",NOW(),Z9),"") | AB9: =AE9 -> Done | AC9: Dian Hasanudin | AD9: =if(AC9<>"", if(AD9="",NOW(),AD9),"") -> 46162.677 | AE9: Done | AF9: =if(AE9="Done", if(AF9="",NOW(),AF9),"") -> 46162.686 | AG9: 1 | AI9: =E9 -> 2 | AJ9: Faaidh Abdurrazzak | AK9: =if(AJ9<>"", if(AK9="",NOW(),AK9),"") -> 46162.674 | AL9: Done | AM9: =if(AL9="Done", if(AM9="",NOW(),AM9),"") -> 46163.624 | AN9: =IF(AND(AK9<>"",AM9<>""),(AM9-AK9)*1440,"") -> 1368.4846 | AO9: =IF( INT(AK9)=INT(AM9), IF( AND(MOD(AK9,1)<TIME(12,0,0), MOD(AM9,1)>TIME(12,0,0)), 60, 0 ), IF( MOD(AM9,1)<=TIME(12,0,0), (INT(AM9)-INT(AK9))*960, (INT(AM9)-INT(AK9))*1020 ) ) -> 1020 | AP9: =(AN9-AO9)/60 -> 5.8080767 | AQ9: =AT9 | AS9: =if(AR9<>"", if(AS9="",NOW(),AS9),"") | AU9: =if(AT9="Done", if(AU9="",NOW(),AU9),"") | AW9: =AZ9 | AY9: =if(AX9<>"", if(AY9="",NOW(),AY9),"") | BA9: =if(AZ9="Done", if(BA9="",NOW(),BA9),"") | BC9: =BF9 | BE9: =if(BD9<>"", if(BE9="",NOW(),BE9),"") | BG9: =if(BF9="Done", if(BG9="",NOW(),BG9),"") | BH9: 0
A10: =IF(B10="","",COUNTA($B$3:B10)) -> 8 | B10: The Eagle's Nest (Operasi Cakar Elang) | C10: =IF(B10="","", "PDSSVB"&TEXT(COUNTA($B$3:B10),"000")) -> PDSSVB008 | D10: 2 | E10: 2 | F10: Dian Hasanudin | H10: =D10 -> 2 | I10: Siti Anisah Rhamadani | J10: =if(I10<>"", if(J10="",NOW(),J10),"") -> 46155.613 | K10: Done | L10: =if(K10="Done", if(L10="",NOW(),L10),"") -> 46157.427 | M10: =IF(AND(J10<>"",L10<>""),(L10-J10)*1440,"") -> 2612.2289 | N10: =IF( INT(J10)=INT(L10), IF( AND(MOD(J10,1)<TIME(12,0,0), MOD(L10,1)>TIME(12,0,0)), 60, 0 ), IF( MOD(L10,1)<=TIME(12,0,0), (INT(L10)-INT(J10))*960, (INT(L10)-INT(J10))*1020 ) ) -> 1920 | O10: =(M10-N10)/60 -> 11.537148 | P10: =S10 | R10: =if(Q10<>"", if(R10="",NOW(),R10),"") | T10: =if(S10="Done", if(T10="",NOW(),T10),"") | V10: =Y10 | X10: =if(W10<>"", if(X10="",NOW(),X10),"") | Z10: =if(Y10="Done", if(Z10="",NOW(),Z10),"") | AB10: =AE10 -> Done | AC10: Dian Hasanudin | AD10: =if(AC10<>"", if(AD10="",NOW(),AD10),"") -> 46163.588 | AE10: Done | AF10: =if(AE10="Done", if(AF10="",NOW(),AF10),"") -> 46163.621 | AG10: 1 | AI10: =E10 -> 2 | AJ10: Faaidh Abdurrazzak | AK10: =if(AJ10<>"", if(AK10="",NOW(),AK10),"") -> 46163.624 | AL10: Done | AM10: =if(AL10="Done", if(AM10="",NOW(),AM10),"") -> 46164.699 | AN10: =IF(AND(AK10<>"",AM10<>""),(AM10-AK10)*1440,"") -> 1548.2859 | AO10: =IF( INT(AK10)=INT(AM10), IF( AND(MOD(AK10,1)<TIME(12,0,0), MOD(AM10,1)>TIME(12,0,0)), 60, 0 ), IF( MOD(AM10,1)<=TIME(12,0,0), (INT(AM10)-INT(AK10))*960, (INT(AM10)-INT(AK10))*1020 ) ) -> 1020 | AP10: =(AN10-AO10)/60 -> 8.8047644 | AQ10: =AT10 | AS10: =if(AR10<>"", if(AS10="",NOW(),AS10),"") | AU10: =if(AT10="Done", if(AU10="",NOW(),AU10),"") | AW10: =AZ10 | AY10: =if(AX10<>"", if(AY10="",NOW(),AY10),"") | BA10: =if(AZ10="Done", if(BA10="",NOW(),BA10),"") | BC10: =BF10 | BE10: =if(BD10<>"", if(BE10="",NOW(),BE10),"") | BG10: =if(BF10="Done", if(BG10="",NOW(),BG10),"") | BH10: 0
A11: =IF(B11="","",COUNTA($B$3:B11)) -> 9 | B11: Campus Panic (Serangan Kampus) | C11: =IF(B11="","", "PDSSVB"&TEXT(COUNTA($B$3:B11),"000")) -> PDSSVB009 | D11: 2 | E11: 2 | F11: Dian Hasanudin | H11: =D11 -> 2 | I11: Siti Anisah Rhamadani | J11: =if(I11<>"", if(J11="",NOW(),J11),"") -> 46155.625 | K11: Done | L11: =if(K11="Done", if(L11="",NOW(),L11),"") -> 46157.502 | M11: =IF(AND(J11<>"",L11<>""),(L11-J11)*1440,"") -> 2702.9538 | N11: =IF( INT(J11)=INT(L11), IF( AND(MOD(J11,1)<TIME(12,0,0), MOD(L11,1)>TIME(12,0,0)), 60, 0 ), IF( MOD(L11,1)<=TIME(12,0,0), (INT(L11)-INT(J11))*960, (INT(L11)-INT(J11))*1020 ) ) -> 2040 | O11: =(M11-N11)/60 -> 11.04923 | P11: =S11 | R11: =if(Q11<>"", if(R11="",NOW(),R11),"") | T11: =if(S11="Done", if(T11="",NOW(),T11),"") | V11: =Y11 | X11: =if(W11<>"", if(X11="",NOW(),X11),"") | Z11: =if(Y11="Done", if(Z11="",NOW(),Z11),"") | AB11: =AE11 -> Done | AC11: Dian Hasanudin | AD11: =if(AC11<>"", if(AD11="",NOW(),AD11),"") -> 46163.634 | AE11: Done | AF11: =if(AE11="Done", if(AF11="",NOW(),AF11),"") -> 46163.681 | AG11: 1 | AI11: =E11 -> 2 | AJ11: Muhamad Ade Saputra | AK11: =if(AJ11<>"", if(AK11="",NOW(),AK11),"") -> 46163.684 | AL11: Done | AM11: =if(AL11="Done", if(AM11="",NOW(),AM11),"") -> 46167.423 | AN11: =IF(AND(AK11<>"",AM11<>""),(AM11-AK11)*1440,"") -> 5384.0733 | AO11: =IF( INT(AK11)=INT(AM11), IF( AND(MOD(AK11,1)<TIME(12,0,0), MOD(AM11,1)>TIME(12,0,0)), 60, 0 ), IF( MOD(AM11,1)<=TIME(12,0,0), (INT(AM11)-INT(AK11))*960, (INT(AM11)-INT(AK11))*1020 ) ) -> 3840 | AP11: =(AN11-AO11)/60 -> 25.734554 | AQ11: =AT11 | AS11: =if(AR11<>"", if(AS11="",NOW(),AS11),"") | AU11: =if(AT11="Done", if(AU11="",NOW(),AU11),"") | AW11: =AZ11 | AY11: =if(AX11<>"", if(AY11="",NOW(),AY11),"") | BA11: =if(AZ11="Done", if(BA11="",NOW(),BA11),"") | BC11: =BF11 | BE11: =if(BD11<>"", if(BE11="",NOW(),BE11),"") | BG11: =if(BF11="Done", if(BG11="",NOW(),BG11),"") | BH11: 0
A12: =IF(B12="","",COUNTA($B$3:B12)) -> 10 | B12: Subway Station (Sabotase Stasiun Kereta Bawah Tanah) | C12: =IF(B12="","", "PDSSVB"&TEXT(COUNTA($B$3:B12),"000")) -> PDSSVB010 | D12: 2 | E12: 2 | F12: Dian Hasanudin | H12: =D12 -> 2 | I12: Siti Anisah Rhamadani | J12: =if(I12<>"", if(J12="",NOW(),J12),"") -> 46155.659 | K12: Done | L12: =if(K12="Done", if(L12="",NOW(),L12),"") -> 46157.502 | M12: =IF(AND(J12<>"",L12<>""),(L12-J12)*1440,"") -> 2654.2645 | N12: =IF( INT(J12)=INT(L12), IF( AND(MOD(J12,1)<TIME(12,0,0), MOD(L12,1)>TIME(12,0,0)), 60, 0 ), IF( MOD(L12,1)<=TIME(12,0,0), (INT(L12)-INT(J12))*960, (INT(L12)-INT(J12))*1020 ) ) -> 2040 | O12: =(M12-N12)/60 -> 10.237741 | P12: =S12 | R12: =if(Q12<>"", if(R12="",NOW(),R12),"") | T12: =if(S12="Done", if(T12="",NOW(),T12),"") | V12: =Y12 | X12: =if(W12<>"", if(X12="",NOW(),X12),"") | Z12: =if(Y12="Done", if(Z12="",NOW(),Z12),"") | AB12: =AE12 -> Done | AC12: Dian Hasanudin | AD12: =if(AC12<>"", if(AD12="",NOW(),AD12),"") -> 46164.57 | AE12: Done | AF12: =if(AE12="Done", if(AF12="",NOW(),AF12),"") -> 46164.617 | AG12: 1 | AI12: =E12 -> 2 | AJ12: Muhamad Ade Saputra | AK12: =if(AJ12<>"", if(AK12="",NOW(),AK12),"") -> 46167.423 | AL12: Done | AM12: =if(AL12="Done", if(AM12="",NOW(),AM12),"") -> 46167.633 | AN12: =IF(AND(AK12<>"",AM12<>""),(AM12-AK12)*1440,"") -> 302.53002 | AO12: =IF( INT(AK12)=INT(AM12), IF( AND(MOD(AK12,1)<TIME(12,0,0), MOD(AM12,1)>TIME(12,0,0)), 60, 0 ), IF( MOD(AM12,1)<=TIME(12,0,0), (INT(AM12)-INT(AK12))*960, (INT(AM12)-INT(AK12))*1020 ) ) -> 60 | AP12: =(AN12-AO12)/60 -> 4.0421669 | AQ12: =AT12 | AS12: =if(AR12<>"", if(AS12="",NOW(),AS12),"") | AU12: =if(AT12="Done", if(AU12="",NOW(),AU12),"") | AW12: =AZ12 | AY12: =if(AX12<>"", if(AY12="",NOW(),AY12),"") | BA12: =if(AZ12="Done", if(BA12="",NOW(),BA12),"") | BC12: =BF12 | BE12: =if(BD12<>"", if(BE12="",NOW(),BE12),"") | BG12: =if(BF12="Done", if(BG12="",NOW(),BG12),"") | BH12: 0
A13: =IF(B13="","",COUNTA($B$3:B13)) -> 11 | B13: Power Outage Hospital (Serbuan Penjarah Fasilitas Medis) | C13: =IF(B13="","", "PDSSVB"&TEXT(COUNTA($B$3:B13),"000")) -> PDSSVB011 | D13: 2 | E13: 2 | F13: Dian Hasanudin | H13: =D13 -> 2 | I13: Siti Anisah Rhamadani | J13: =if(I13<>"", if(J13="",NOW(),J13),"") -> 46157.42 | K13: Done | L13: =if(K13="Done", if(L13="",NOW(),L13),"") -> 46157.42 | M13: =IF(AND(J13<>"",L13<>""),(L13-J13)*1440,"") -> 0 | N13: =IF( INT(J13)=INT(L13), IF( AND(MOD(J13,1)<TIME(12,0,0), MOD(L13,1)>TIME(12,0,0)), 60, 0 ), IF( MOD(L13,1)<=TIME(12,0,0), (INT(L13)-INT(J13))*960, (INT(L13)-INT(J13))*1020 ) ) -> 0 | O13: =(M13-N13)/60 -> 0 | P13: =S13 | R13: =if(Q13<>"", if(R13="",NOW(),R13),"") | T13: =if(S13="Done", if(T13="",NOW(),T13),"") | V13: =Y13 | X13: =if(W13<>"", if(X13="",NOW(),X13),"") | Z13: =if(Y13="Done", if(Z13="",NOW(),Z13),"") | AB13: =AE13 -> Done | AC13: Dian Hasanudin | AD13: =if(AC13<>"", if(AD13="",NOW(),AD13),"") -> 46167.414 | AE13: Done | AF13: =if(AE13="Done", if(AF13="",NOW(),AF13),"") -> 46167.457 | AG13: 1 | AI13: =E13 -> 2 | AJ13: Faaidh Abdurrazzak | AK13: =if(AJ13<>"", if(AK13="",NOW(),AK13),"") -> 46167.58 | AL13: Done | AM13: =if(AL13="Done", if(AM13="",NOW(),AM13),"") -> 46168.679 | AN13: =IF(AND(AK13<>"",AM13<>""),(AM13-AK13)*1440,"") -> 1581.2963 | AO13: =IF( INT(AK13)=INT(AM13), IF( AND(MOD(AK13,1)<TIME(12,0,0), MOD(AM13,1)>TIME(12,0,0)), 60, 0 ), IF( MOD(AM13,1)<=TIME(12,0,0), (INT(AM13)-INT(AK13))*960, (INT(AM13)-INT(AK13))*1020 ) ) -> 1020 | AP13: =(AN13-AO13)/60 -> 9.3549381 | AQ13: =AT13 | AS13: =if(AR13<>"", if(AS13="",NOW(),AS13),"") | AU13: =if(AT13="Done", if(AU13="",NOW(),AU13),"") | AW13: =AZ13 | AY13: =if(AX13<>"", if(AY13="",NOW(),AY13),"") | BA13: =if(AZ13="Done", if(BA13="",NOW(),BA13),"") | BC13: =BF13 | BE13: =if(BD13<>"", if(BE13="",NOW(),BE13),"") | BG13: =if(BF13="Done", if(BG13="",NOW(),BG13),"") | BH13: 0
A14: =IF(B14="","",COUNTA($B$3:B14)) -> 12 | B14: Midnight Harbour (Penyergapan Dermaga Malam) | C14: =IF(B14="","", "PDSSVB"&TEXT(COUNTA($B$3:B14),"000")) -> PDSSVB012 | D14: 2 | E14: 2 | F14: Dian Hasanudin | H14: =D14 -> 2 | I14: Siti Anisah Rhamadani | J14: =if(I14<>"", if(J14="",NOW(),J14),"") -> 46157.502 | K14: Done | L14: =if(K14="Done", if(L14="",NOW(),L14),"") -> 46157.584 | M14: =IF(AND(J14<>"",L14<>""),(L14-J14)*1440,"") -> 117.3293 | N14: =IF( INT(J14)=INT(L14), IF( AND(MOD(J14,1)<TIME(12,0,0), MOD(L14,1)>TIME(12,0,0)), 60, 0 ), IF( MOD(L14,1)<=TIME(12,0,0), (INT(L14)-INT(J14))*960, (INT(L14)-INT(J14))*1020 ) ) -> 0 | O14: =(M14-N14)/60 -> 1.9554883 | P14: =S14 | R14: =if(Q14<>"", if(R14="",NOW(),R14),"") | T14: =if(S14="Done", if(T14="",NOW(),T14),"") | V14: =Y14 | X14: =if(W14<>"", if(X14="",NOW(),X14),"") | Z14: =if(Y14="Done", if(Z14="",NOW(),Z14),"") | AB14: =AE14 -> Done | AC14: Dian Hasanudin | AD14: =if(AC14<>"", if(AD14="",NOW(),AD14),"") -> 46167.46 | AE14: Done | AF14: =if(AE14="Done", if(AF14="",NOW(),AF14),"") -> 46167.5 | AG14: 1 | AI14: =E14 -> 2 | AJ14: Muhamad Ade Saputra | AK14: =if(AJ14<>"", if(AK14="",NOW(),AK14),"") -> 46167.633 | AL14: Done | AM14: =if(AL14="Done", if(AM14="",NOW(),AM14),"") -> 46168.679 | AN14: =IF(AND(AK14<>"",AM14<>""),(AM14-AK14)*1440,"") -> 1506.3087 | AO14: =IF( INT(AK14)=INT(AM14), IF( AND(MOD(AK14,1)<TIME(12,0,0), MOD(AM14,1)>TIME(12,0,0)), 60, 0 ), IF( MOD(AM14,1)<=TIME(12,0,0), (INT(AM14)-INT(AK14))*960, (INT(AM14)-INT(AK14))*1020 ) ) -> 1020 | AP14: =(AN14-AO14)/60 -> 8.105145 | AQ14: =AT14 | AS14: =if(AR14<>"", if(AS14="",NOW(),AS14),"") | AU14: =if(AT14="Done", if(AU14="",NOW(),AU14),"") | AW14: =AZ14 | AY14: =if(AX14<>"", if(AY14="",NOW(),AY14),"") | BA14: =if(AZ14="Done", if(BA14="",NOW(),BA14),"") | BC14: =BF14 | BE14: =if(BD14<>"", if(BE14="",NOW(),BE14),"") | BG14: =if(BF14="Done", if(BG14="",NOW(),BG14),"") | BH14: 0
A15: =IF(B15="","",COUNTA($B$3:B15)) -> 13 | B15: Phantom Protocol (Operasi Bayang Hitam) | C15: =IF(B15="","", "PDSSVB"&TEXT(COUNTA($B$3:B15),"000")) -> PDSSVB013 | D15: 2 | E15: 2 | F15: Dian Hasanudin | H15: =D15 -> 2 | I15: Siti Anisah Rhamadani | J15: =if(I15<>"", if(J15="",NOW(),J15),"") -> 46157.584 | K15: Done | L15: =if(K15="Done", if(L15="",NOW(),L15),"") -> 46157.633 | M15: =IF(AND(J15<>"",L15<>""),(L15-J15)*1440,"") -> 71.392283 | N15: =IF( INT(J15)=INT(L15), IF( AND(MOD(J15,1)<TIME(12,0,0), MOD(L15,1)>TIME(12,0,0)), 60, 0 ), IF( MOD(L15,1)<=TIME(12,0,0), (INT(L15)-INT(J15))*960, (INT(L15)-INT(J15))*1020 ) ) -> 0 | O15: =(M15-N15)/60 -> 1.1898714 | P15: =S15 | R15: =if(Q15<>"", if(R15="",NOW(),R15),"") | T15: =if(S15="Done", if(T15="",NOW(),T15),"") | V15: =Y15 | X15: =if(W15<>"", if(X15="",NOW(),X15),"") | Z15: =if(Y15="Done", if(Z15="",NOW(),Z15),"") | AB15: =AE15 -> Done | AC15: Dian Hasanudin | AD15: =if(AC15<>"", if(AD15="",NOW(),AD15),"") -> 46167.608 | AE15: Done | AF15: =if(AE15="Done", if(AF15="",NOW(),AF15),"") -> 46167.618 | AG15: 1 | AI15: =E15 -> 2 | AJ15: Faaidh Abdurrazzak | AK15: =if(AJ15<>"", if(AK15="",NOW(),AK15),"") -> 46175.377 | AL15: Done | AM15: =if(AL15="Done", if(AM15="",NOW(),AM15),"") -> 46175.576 | AN15: =IF(AND(AK15<>"",AM15<>""),(AM15-AK15)*1440,"") -> 287.94103 | AO15: =IF( INT(AK15)=INT(AM15), IF( AND(MOD(AK15,1)<TIME(12,0,0), MOD(AM15,1)>TIME(12,0,0)), 60, 0 ), IF( MOD(AM15,1)<=TIME(12,0,0), (INT(AM15)-INT(AK15))*960, (INT(AM15)-INT(AK15))*1020 ) ) -> 60 | AP15: =(AN15-AO15)/60 -> 3.7990172 | AQ15: =AT15 | AS15: =if(AR15<>"", if(AS15="",NOW(),AS15),"") | AU15: =if(AT15="Done", if(AU15="",NOW(),AU15),"") | AW15: =AZ15 | AY15: =if(AX15<>"", if(AY15="",NOW(),AY15),"") | BA15: =if(AZ15="Done", if(BA15="",NOW(),BA15),"") | BC15: =BF15 | BE15: =if(BD15<>"", if(BE15="",NOW(),BE15),"") | BG15: =if(BF15="Done", if(BG15="",NOW(),BG15),"") | BH15: 0
... A17: =IF(B17="","",COUNTA($B$3:B17)) -> 15 | B17: Last Light (Operasi Fajar Terakhir) | C17: =IF(B17="","", "PDSSVB"&TEXT(COUNTA($B$3:B17),"000")) -> PDSSVB015 | D17: 2 | E17: 2 | F17: Dian Hasanudin | H17: =D17 -> 2 | I17: Siti Anisah Rhamadani | J17: =if(I17<>"", if(J17="",NOW(),J17),"") -> 46157.673 | K17: Done | L17: =if(K17="Done", if(L17="",NOW(),L17),"") -> 46157.696 | M17: =IF(AND(J17<>"",L17<>""),(L17-J17)*1440,"") -> 32.7933 | N17: =IF( INT(J17)=INT(L17), IF( AND(MOD(J17,1)<TIME(12,0,0), MOD(L17,1)>TIME(12,0,0)), 60, 0 ), IF( MOD(L17,1)<=TIME(12,0,0), (INT(L17)-INT(J17))*960, (INT(L17)-INT(J17))*1020 ) ) -> 0 | O17: =(M17-N17)/60 -> 0.546555 | P17: =S17 | R17: =if(Q17<>"", if(R17="",NOW(),R17),"") | T17: =if(S17="Done", if(T17="",NOW(),T17),"") | V17: =Y17 | X17: =if(W17<>"", if(X17="",NOW(),X17),"") | Z17: =if(Y17="Done", if(Z17="",NOW(),Z17),"") | AB17: =AE17 -> Done | AC17: Dian Hasanudin | AD17: =if(AC17<>"", if(AD17="",NOW(),AD17),"") -> 46168.584 | AE17: Done | AF17: =if(AE17="Done", if(AF17="",NOW(),AF17),"") -> 46168.629 | AG17: 1 | AI17: =E17 -> 2 | AJ17: Faaidh Abdurrazzak | AK17: =if(AJ17<>"", if(AK17="",NOW(),AK17),"") -> 46175.577 | AL17: Done | AM17: =if(AL17="Done", if(AM17="",NOW(),AM17),"") -> 46176.539 | AN17: =IF(AND(AK17<>"",AM17<>""),(AM17-AK17)*1440,"") -> 1385.0837 | AO17: =IF( INT(AK17)=INT(AM17), IF( AND(MOD(AK17,1)<TIME(12,0,0), MOD(AM17,1)>TIME(12,0,0)), 60, 0 ), IF( MOD(AM17,1)<=TIME(12,0,0), (INT(AM17)-INT(AK17))*960, (INT(AM17)-INT(AK17))*1020 ) ) -> 1020 | AP17: =(AN17-AO17)/60 -> 6.0847275 | AQ17: =AT17 | AS17: =if(AR17<>"", if(AS17="",NOW(),AS17),"") | AU17: =if(AT17="Done", if(AU17="",NOW(),AU17),"") | AW17: =AZ17 | AY17: =if(AX17<>"", if(AY17="",NOW(),AY17),"") | BA17: =if(AZ17="Done", if(BA17="",NOW(),BA17),"") | BC17: =BF17 | BE17: =if(BD17<>"", if(BE17="",NOW(),BE17),"") | BG17: =if(BF17="Done", if(BG17="",NOW(),BG17),"") | BH17: 0
A18: =IF(B18="","",COUNTA($B$3:B18)) | C18: =IF(B18="","", "PDSSVB"&TEXT(COUNTA($B$3:B18),"000")) | H18: =D18 | J18: =if(I18<>"", if(J18="",NOW(),J18),"") | L18: =if(K18="Done", if(L18="",NOW(),L18),"") | M18: =IF(AND(J18<>"",L18<>""),(L18-J18)*1440,"") | N18: =IF( INT(J18)=INT(L18), IF( AND(MOD(J18,1)<TIME(12,0,0), MOD(L18,1)>TIME(12,0,0)), 60, 0 ), IF( MOD(L18,1)<=TIME(12,0,0), (INT(L18)-INT(J18))*960, (INT(L18)-INT(J18))*1020 ) ) -> 0 | O18: =(M18-N18)/60 -> 0 | P18: =S18 | R18: =if(Q18<>"", if(R18="",NOW(),R18),"") | T18: =if(S18="Done", if(T18="",NOW(),T18),"") | V18: =Y18 | X18: =if(W18<>"", if(X18="",NOW(),X18),"") | Z18: =if(Y18="Done", if(Z18="",NOW(),Z18),"") | AB18: =AE18 | AD18: =if(AC18<>"", if(AD18="",NOW(),AD18),"") | AF18: =if(AE18="Done", if(AF18="",NOW(),AF18),"") | AG18: 0 | AI18: =E18 | AK18: =if(AJ18<>"", if(AK18="",NOW(),AK18),"") | AM18: =if(AL18="Done", if(AM18="",NOW(),AM18),"") | AN18: =IF(AND(AK18<>"",AM18<>""),(AM18-AK18)*1440,"") | AO18: =IF( INT(AK18)=INT(AM18), IF( AND(MOD(AK18,1)<TIME(12,0,0), MOD(AM18,1)>TIME(12,0,0)), 60, 0 ), IF( MOD(AM18,1)<=TIME(12,0,0), (INT(AM18)-INT(AK18))*960, (INT(AM18)-INT(AK18))*1020 ) ) -> 0 | AP18: =(AN18-AO18)/60 -> 0 | AQ18: =AT18 | AS18: =if(AR18<>"", if(AS18="",NOW(),AS18),"") | AU18: =if(AT18="Done", if(AU18="",NOW(),AU18),"") | AW18: =AZ18 | AY18: =if(AX18<>"", if(AY18="",NOW(),AY18),"") | BA18: =if(AZ18="Done", if(BA18="",NOW(),BA18),"") | BC18: =BF18 | BE18: =if(BD18<>"", if(BE18="",NOW(),BE18),"") | BG18: =if(BF18="Done", if(BG18="",NOW(),BG18),"") | BH18: 0
